  0%|          | 0/369 [00:00<?, ?it/s]  0%|          | 1/369 [00:02<13:10,  2.15s/it]  1%|          | 2/369 [00:04<14:45,  2.41s/it]  1%|          | 3/369 [00:06<13:36,  2.23s/it]  1%|          | 4/369 [00:10<16:17,  2.68s/it]  1%|▏         | 5/369 [01:03<2:07:04, 20.95s/it]llm_build/f8d5edbc-2871-11f0-8ac8-e10f5b0b7eea/Solution.cpp: In function ‘int main()’:
llm_build/f8d5edbc-2871-11f0-8ac8-e10f5b0b7eea/Solution.cpp:22:35: error: conversion from ‘time_point<[...],duration<[...],ratio<216,[...]>>>’ to non-scalar type ‘time_point<[...],duration<[...],ratio<86400,[...]>>>’ requested
   22 |     sys_days one_year_ago = today - years{1};
      |                             ~~~~~~^~~~~~~~~~
  2%|▏         | 6/369 [01:06<1:29:22, 14.77s/it]  2%|▏         | 7/369 [01:08<1:04:45, 10.73s/it]  2%|▏         | 8/369 [01:12<51:49,  8.61s/it]    2%|▏         | 9/369 [02:08<2:19:56, 23.32s/it]  3%|▎         | 10/369 [02:10<1:40:41, 16.83s/it]  3%|▎         | 11/369 [02:12<1:13:34, 12.33s/it]  3%|▎         | 12/369 [03:03<2:22:41, 23.98s/it]  4%|▎         | 13/369 [03:10<1:51:14, 18.75s/it]  4%|▍         | 14/369 [03:13<1:24:07, 14.22s/it]llm_build/65ea9c18-2872-11f0-8acb-e10f5b0b7eea/Solution.cpp: In function ‘int main()’:
llm_build/65ea9c18-2872-11f0-8acb-e10f5b0b7eea/Solution.cpp:23:35: error: conversion from ‘time_point<[...],duration<[...],ratio<216,[...]>>>’ to non-scalar type ‘time_point<[...],duration<[...],ratio<86400,[...]>>>’ requested
   23 |     sys_days one_year_ago = today - years{1};
      |                             ~~~~~~^~~~~~~~~~
  4%|▍         | 15/369 [04:09<2:36:45, 26.57s/it]  4%|▍         | 16/369 [04:14<1:58:40, 20.17s/it]  5%|▍         | 17/369 [05:07<2:56:45, 30.13s/it]  5%|▍         | 18/369 [05:09<2:06:59, 21.71s/it]  5%|▌         | 19/369 [05:11<1:32:10, 15.80s/it]  5%|▌         | 20/369 [05:14<1:08:51, 11.84s/it]  6%|▌         | 21/369 [05:16<51:56,  8.95s/it]    6%|▌         | 22/369 [06:04<1:58:30, 20.49s/it]  6%|▌         | 23/369 [06:06<1:26:40, 15.03s/it]llm_build/ad3dd3f0-2872-11f0-8acb-e10f5b0b7eea/Solution.cpp: In function ‘int main()’:
llm_build/ad3dd3f0-2872-11f0-8acb-e10f5b0b7eea/Solution.cpp:22:35: error: conversion from ‘time_point<[...],duration<[...],ratio<216,[...]>>>’ to non-scalar type ‘time_point<[...],duration<[...],ratio<86400,[...]>>>’ requested
   22 |     sys_days one_year_ago = today - years{1};
      |                             ~~~~~~^~~~~~~~~~
  7%|▋         | 24/369 [06:08<1:04:45, 11.26s/it]  7%|▋         | 25/369 [06:11<48:54,  8.53s/it]    7%|▋         | 26/369 [06:13<38:25,  6.72s/it]  7%|▋         | 27/369 [06:16<32:39,  5.73s/it]  8%|▊         | 28/369 [07:10<1:54:14, 20.10s/it]  8%|▊         | 29/369 [07:12<1:23:44, 14.78s/it]  8%|▊         | 30/369 [07:14<1:01:23, 10.87s/it]  8%|▊         | 31/369 [07:16<46:07,  8.19s/it]    9%|▊         | 32/369 [08:12<2:06:04, 22.45s/it]  9%|▉         | 33/369 [08:14<1:31:38, 16.37s/it]  9%|▉         | 34/369 [08:16<1:07:54, 12.16s/it]  9%|▉         | 35/369 [08:18<51:00,  9.16s/it]   10%|▉         | 36/369 [09:11<2:02:39, 22.10s/it] 10%|█         | 37/369 [09:13<1:29:20, 16.15s/it] 10%|█         | 38/369 [09:15<1:06:01, 11.97s/it] 11%|█         | 39/369 [09:17<49:03,  8.92s/it]   11%|█         | 40/369 [10:16<2:11:02, 23.90s/it] 11%|█         | 41/369 [10:20<1:38:23, 18.00s/it]llm_build/62138f4a-2873-11f0-8ace-e10f5b0b7eea/Solution.cpp: In function ‘int main()’:
llm_build/62138f4a-2873-11f0-8ace-e10f5b0b7eea/Solution.cpp:18:35: error: conversion from ‘time_point<[...],duration<[...],ratio<216,[...]>>>’ to non-scalar type ‘time_point<[...],duration<[...],ratio<86400,[...]>>>’ requested
   18 |     sys_days one_year_ago = today - years{1};
      |                             ~~~~~~^~~~~~~~~~
 11%|█▏        | 42/369 [11:12<2:32:55, 28.06s/it] 12%|█▏        | 43/369 [11:18<1:56:35, 21.46s/it] 12%|█▏        | 44/369 [11:20<1:25:39, 15.81s/it] 12%|█▏        | 45/369 [12:16<2:29:39, 27.72s/it] 12%|█▏        | 46/369 [12:18<1:47:20, 19.94s/it] 13%|█▎        | 47/369 [12:20<1:18:04, 14.55s/it] 13%|█▎        | 48/369 [12:24<1:00:57, 11.39s/it] 13%|█▎        | 49/369 [13:06<1:50:00, 20.63s/it] 14%|█▎        | 50/369 [13:12<1:27:05, 16.38s/it] 14%|█▍        | 51/369 [13:14<1:03:46, 12.03s/it] 14%|█▍        | 52/369 [13:16<47:31,  9.00s/it]   14%|█▍        | 53/369 [13:18<36:02,  6.84s/it] 15%|█▍        | 54/369 [13:20<27:47,  5.29s/it] 15%|█▍        | 55/369 [13:24<25:42,  4.91s/it] 15%|█▌        | 56/369 [14:06<1:24:20, 16.17s/it] 15%|█▌        | 57/369 [14:19<1:18:24, 15.08s/it] 16%|█▌        | 58/369 [14:21<58:16, 11.24s/it]  llm_build/d411d12e-2873-11f0-8ad2-e10f5b0b7eea/Solution.cpp: In function ‘int main()’:
llm_build/d411d12e-2873-11f0-8ad2-e10f5b0b7eea/Solution.cpp:19:39: error: conversion from ‘time_point<[...],duration<[...],ratio<54,[...]>>>’ to non-scalar type ‘time_point<[...],duration<[...],ratio<86400,[...]>>>’ requested
   19 |     sys_days a_month_ago = today_days - months{1};
      |                            ~~~~~~~~~~~^~~~~~~~~~~
 16%|█▌        | 59/369 [14:23<43:45,  8.47s/it]llm_build/ee401420-2873-11f0-8ad2-e10f5b0b7eea/Solution.cpp: In function ‘int main()’:
llm_build/ee401420-2873-11f0-8ad2-e10f5b0b7eea/Solution.cpp:19:40: error: conversion from ‘time_point<[...],duration<[...],ratio<216,[...]>>>’ to non-scalar type ‘time_point<[...],duration<[...],ratio<86400,[...]>>>’ requested
   19 |     sys_days one_year_ago = today_days - years{1};
      |                             ~~~~~~~~~~~^~~~~~~~~~
 16%|█▋        | 60/369 [15:07<1:38:33, 19.14s/it] 17%|█▋        | 61/369 [15:18<1:26:33, 16.86s/it] 17%|█▋        | 62/369 [15:21<1:03:57, 12.50s/it]llm_build/f84edf3c-2873-11f0-8ad3-e10f5b0b7eea/Solution.cpp: In function ‘int main()’:
llm_build/f84edf3c-2873-11f0-8ad3-e10f5b0b7eea/Solution.cpp:19:33: error: conversion from ‘time_point<[...],duration<[...],ratio<3600>>>’ to non-scalar type ‘time_point<[...],duration<[...],ratio<86400>>>’ requested
   19 |     sys_days later = today_days + hours{24};
      |                      ~~~~~~~~~~~^~~~~~~~~~~
 17%|█▋        | 63/369 [15:24<49:07,  9.63s/it]   17%|█▋        | 64/369 [16:27<2:10:13, 25.62s/it] 18%|█▊        | 65/369 [17:07<2:32:43, 30.14s/it] 18%|█▊        | 66/369 [17:20<2:05:02, 24.76s/it] 18%|█▊        | 67/369 [17:22<1:30:36, 18.00s/it]llm_build/400fc12e-2874-11f0-8ad4-e10f5b0b7eea/Solution.cpp: In function ‘int main()’:
llm_build/400fc12e-2874-11f0-8ad4-e10f5b0b7eea/Solution.cpp:19:39: error: conversion from ‘time_point<[...],duration<[...],ratio<54,[...]>>>’ to non-scalar type ‘time_point<[...],duration<[...],ratio<86400,[...]>>>’ requested
   19 |     sys_days a_month_ago = today_days - months{1};
      |                            ~~~~~~~~~~~^~~~~~~~~~~
Execute error: 
Traceback (most recent call last):
  File "/home/doyle/Documents/COS484/COS484_PAL/.venv/lib/python3.10/site-packages/pal/core/interface.py", line 185, in run
    exec_result = self.execute(code)
  File "/home/doyle/Documents/COS484/COS484_PAL/.venv/lib/python3.10/site-packages/pal/core/interface.py", line 114, in execute
    self.runtime.exec_code('\n'.join(code))
  File "/home/doyle/Documents/COS484/COS484_PAL/.venv/lib/python3.10/site-packages/pal/core/runtime.py", line 206, in exec_code
    result = subprocess.run([f"llm_build/{str(random_uuid)}/Solution"], capture_output=True)
  File "/usr/lib/python3.10/subprocess.py", line 503, in run
    with Popen(*popenargs, **kwargs) as process:
  File "/usr/lib/python3.10/subprocess.py", line 971, in __init__
    self._execute_child(args, executable, preexec_fn, close_fds,
  File "/usr/lib/python3.10/subprocess.py", line 1863, in _execute_child
    raise child_exception_type(errno_num, err_msg, err_filename)
FileNotFoundError: [Errno 2] No such file or directory: 'llm_build/f8d5edbc-2871-11f0-8ac8-e10f5b0b7eea/Solution'

Execute error: 
Traceback (most recent call last):
  File "/home/doyle/Documents/COS484/COS484_PAL/.venv/lib/python3.10/site-packages/pal/core/interface.py", line 185, in run
    exec_result = self.execute(code)
  File "/home/doyle/Documents/COS484/COS484_PAL/.venv/lib/python3.10/site-packages/pal/core/interface.py", line 114, in execute
    self.runtime.exec_code('\n'.join(code))
  File "/home/doyle/Documents/COS484/COS484_PAL/.venv/lib/python3.10/site-packages/pal/core/runtime.py", line 206, in exec_code
    result = subprocess.run([f"llm_build/{str(random_uuid)}/Solution"], capture_output=True)
  File "/usr/lib/python3.10/subprocess.py", line 503, in run
    with Popen(*popenargs, **kwargs) as process:
  File "/usr/lib/python3.10/subprocess.py", line 971, in __init__
    self._execute_child(args, executable, preexec_fn, close_fds,
  File "/usr/lib/python3.10/subprocess.py", line 1863, in _execute_child
    raise child_exception_type(errno_num, err_msg, err_filename)
FileNotFoundError: [Errno 2] No such file or directory: 'llm_build/65ea9c18-2872-11f0-8acb-e10f5b0b7eea/Solution'

Execute error: 
Traceback (most recent call last):
  File "/home/doyle/Documents/COS484/COS484_PAL/.venv/lib/python3.10/site-packages/pal/core/interface.py", line 185, in run
    exec_result = self.execute(code)
  File "/home/doyle/Documents/COS484/COS484_PAL/.venv/lib/python3.10/site-packages/pal/core/interface.py", line 114, in execute
    self.runtime.exec_code('\n'.join(code))
  File "/home/doyle/Documents/COS484/COS484_PAL/.venv/lib/python3.10/site-packages/pal/core/runtime.py", line 206, in exec_code
    result = subprocess.run([f"llm_build/{str(random_uuid)}/Solution"], capture_output=True)
  File "/usr/lib/python3.10/subprocess.py", line 503, in run
    with Popen(*popenargs, **kwargs) as process:
  File "/usr/lib/python3.10/subprocess.py", line 971, in __init__
    self._execute_child(args, executable, preexec_fn, close_fds,
  File "/usr/lib/python3.10/subprocess.py", line 1863, in _execute_child
    raise child_exception_type(errno_num, err_msg, err_filename)
FileNotFoundError: [Errno 2] No such file or directory: 'llm_build/ad3dd3f0-2872-11f0-8acb-e10f5b0b7eea/Solution'

Execute error: 
Traceback (most recent call last):
  File "/home/doyle/Documents/COS484/COS484_PAL/.venv/lib/python3.10/site-packages/pal/core/interface.py", line 185, in run
    exec_result = self.execute(code)
  File "/home/doyle/Documents/COS484/COS484_PAL/.venv/lib/python3.10/site-packages/pal/core/interface.py", line 114, in execute
    self.runtime.exec_code('\n'.join(code))
  File "/home/doyle/Documents/COS484/COS484_PAL/.venv/lib/python3.10/site-packages/pal/core/runtime.py", line 206, in exec_code
    result = subprocess.run([f"llm_build/{str(random_uuid)}/Solution"], capture_output=True)
  File "/usr/lib/python3.10/subprocess.py", line 503, in run
    with Popen(*popenargs, **kwargs) as process:
  File "/usr/lib/python3.10/subprocess.py", line 971, in __init__
    self._execute_child(args, executable, preexec_fn, close_fds,
  File "/usr/lib/python3.10/subprocess.py", line 1863, in _execute_child
    raise child_exception_type(errno_num, err_msg, err_filename)
FileNotFoundError: [Errno 2] No such file or directory: 'llm_build/62138f4a-2873-11f0-8ace-e10f5b0b7eea/Solution'

Execute error: 
Traceback (most recent call last):
  File "/home/doyle/Documents/COS484/COS484_PAL/.venv/lib/python3.10/site-packages/pal/core/interface.py", line 185, in run
    exec_result = self.execute(code)
  File "/home/doyle/Documents/COS484/COS484_PAL/.venv/lib/python3.10/site-packages/pal/core/interface.py", line 114, in execute
    self.runtime.exec_code('\n'.join(code))
  File "/home/doyle/Documents/COS484/COS484_PAL/.venv/lib/python3.10/site-packages/pal/core/runtime.py", line 206, in exec_code
    result = subprocess.run([f"llm_build/{str(random_uuid)}/Solution"], capture_output=True)
  File "/usr/lib/python3.10/subprocess.py", line 503, in run
    with Popen(*popenargs, **kwargs) as process:
  File "/usr/lib/python3.10/subprocess.py", line 971, in __init__
    self._execute_child(args, executable, preexec_fn, close_fds,
  File "/usr/lib/python3.10/subprocess.py", line 1863, in _execute_child
    raise child_exception_type(errno_num, err_msg, err_filename)
FileNotFoundError: [Errno 2] No such file or directory: 'llm_build/d411d12e-2873-11f0-8ad2-e10f5b0b7eea/Solution'

Execute error: 
Traceback (most recent call last):
  File "/home/doyle/Documents/COS484/COS484_PAL/.venv/lib/python3.10/site-packages/pal/core/interface.py", line 185, in run
    exec_result = self.execute(code)
  File "/home/doyle/Documents/COS484/COS484_PAL/.venv/lib/python3.10/site-packages/pal/core/interface.py", line 114, in execute
    self.runtime.exec_code('\n'.join(code))
  File "/home/doyle/Documents/COS484/COS484_PAL/.venv/lib/python3.10/site-packages/pal/core/runtime.py", line 206, in exec_code
    result = subprocess.run([f"llm_build/{str(random_uuid)}/Solution"], capture_output=True)
  File "/usr/lib/python3.10/subprocess.py", line 503, in run
    with Popen(*popenargs, **kwargs) as process:
  File "/usr/lib/python3.10/subprocess.py", line 971, in __init__
    self._execute_child(args, executable, preexec_fn, close_fds,
  File "/usr/lib/python3.10/subprocess.py", line 1863, in _execute_child
    raise child_exception_type(errno_num, err_msg, err_filename)
FileNotFoundError: [Errno 2] No such file or directory: 'llm_build/ee401420-2873-11f0-8ad2-e10f5b0b7eea/Solution'

Execute error: 
Traceback (most recent call last):
  File "/home/doyle/Documents/COS484/COS484_PAL/.venv/lib/python3.10/site-packages/pal/core/interface.py", line 185, in run
    exec_result = self.execute(code)
  File "/home/doyle/Documents/COS484/COS484_PAL/.venv/lib/python3.10/site-packages/pal/core/interface.py", line 114, in execute
    self.runtime.exec_code('\n'.join(code))
  File "/home/doyle/Documents/COS484/COS484_PAL/.venv/lib/python3.10/site-packages/pal/core/runtime.py", line 206, in exec_code
    result = subprocess.run([f"llm_build/{str(random_uuid)}/Solution"], capture_output=True)
  File "/usr/lib/python3.10/subprocess.py", line 503, in run
    with Popen(*popenargs, **kwargs) as process:
  File "/usr/lib/python3.10/subprocess.py", line 971, in __init__
    self._execute_child(args, executable, preexec_fn, close_fds,
  File "/usr/lib/python3.10/subprocess.py", line 1863, in _execute_child
    raise child_exception_type(errno_num, err_msg, err_filename)
FileNotFoundError: [Errno 2] No such file or directory: 'llm_build/f84edf3c-2873-11f0-8ad3-e10f5b0b7eea/Solution'

Execute error: 
 18%|█▊        | 68/369 [17:24<1:06:40, 13.29s/it]llm_build/417a66fe-2874-11f0-8ad4-e10f5b0b7eea/Solution.cpp: In function ‘int main()’:
llm_build/417a66fe-2874-11f0-8ad4-e10f5b0b7eea/Solution.cpp:23:40: error: conversion from ‘time_point<[...],duration<[...],ratio<216,[...]>>>’ to non-scalar type ‘time_point<[...],duration<[...],ratio<86400,[...]>>>’ requested
   23 |     sys_days one_year_ago = today_days - years{1};
      |                             ~~~~~~~~~~~^~~~~~~~~~
 19%|█▊        | 69/369 [17:26<50:01, 10.00s/it]   19%|█▉        | 70/369 [18:19<1:53:39, 22.81s/it] 19%|█▉        | 71/369 [18:21<1:22:51, 16.68s/it]llm_build/63eea29a-2874-11f0-8ad4-e10f5b0b7eea/Solution.cpp: In function ‘int main()’:
llm_build/63eea29a-2874-11f0-8ad4-e10f5b0b7eea/Solution.cpp:19:33: error: conversion from ‘time_point<[...],duration<[...],ratio<3600>>>’ to non-scalar type ‘time_point<[...],duration<[...],ratio<86400>>>’ requested
   19 |     sys_days later = today_days + hours{24};
      |                      ~~~~~~~~~~~^~~~~~~~~~~
 20%|█▉        | 72/369 [18:24<1:01:55, 12.51s/it]llm_build/655ae4ea-2874-11f0-8ad5-e10f5b0b7eea/Solution.cpp: In function ‘int main()’:
llm_build/655ae4ea-2874-11f0-8ad5-e10f5b0b7eea/Solution.cpp:20:34: error: conversion from ‘time_point<[...],duration<[...],ratio<216,[...]>>>’ to non-scalar type ‘time_point<[...],duration<[...],ratio<86400,[...]>>>’ requested
   20 |     sys_days today = wedding_day + years{50};
      |                      ~~~~~~~~~~~~^~~~~~~~~~~
 20%|█▉        | 73/369 [18:27<46:44,  9.47s/it]  llm_build/69915a08-2874-11f0-8ad5-e10f5b0b7eea/Solution.cpp: In function ‘int main()’:
llm_build/69915a08-2874-11f0-8ad5-e10f5b0b7eea/Solution.cpp:20:35: error: conversion from ‘time_point<[...],duration<[...],ratio<216,[...]>>>’ to non-scalar type ‘time_point<[...],duration<[...],ratio<86400,[...]>>>’ requested
   20 |     sys_days today = wedding_date + years{50};
      |                      ~~~~~~~~~~~~~^~~~~~~~~~~
 20%|██        | 74/369 [18:34<42:57,  8.74s/it]llm_build/7dee4164-2874-11f0-8ad5-e10f5b0b7eea/Solution.cpp: In function ‘int main()’:
llm_build/7dee4164-2874-11f0-8ad5-e10f5b0b7eea/Solution.cpp:20:34: error: conversion from ‘time_point<[...],duration<[...],ratio<216,[...]>>>’ to non-scalar type ‘time_point<[...],duration<[...],ratio<86400,[...]>>>’ requested
   20 |     sys_days today = wedding_day + years{50};
      |                      ~~~~~~~~~~~~^~~~~~~~~~~
 20%|██        | 75/369 [19:08<1:20:15, 16.38s/it]llm_build/87af70a6-2874-11f0-8ad6-e10f5b0b7eea/Solution.cpp: In function ‘int main()’:
llm_build/87af70a6-2874-11f0-8ad6-e10f5b0b7eea/Solution.cpp:20:35: error: conversion from ‘time_point<[...],duration<[...],ratio<216,[...]>>>’ to non-scalar type ‘time_point<[...],duration<[...],ratio<86400,[...]>>>’ requested
   20 |     sys_days today = wedding_date + years{50};
      |                      ~~~~~~~~~~~~~^~~~~~~~~~~
 21%|██        | 76/369 [19:24<1:20:00, 16.38s/it]llm_build/8a16399c-2874-11f0-8ad6-e10f5b0b7eea/Solution.cpp: In function ‘int main()’:
llm_build/8a16399c-2874-11f0-8ad6-e10f5b0b7eea/Solution.cpp:20:35: error: conversion from ‘time_point<[...],duration<[...],ratio<216,[...]>>>’ to non-scalar type ‘time_point<[...],duration<[...],ratio<86400,[...]>>>’ requested
   20 |     sys_days today = wedding_date + years{50};
      |                      ~~~~~~~~~~~~~^~~~~~~~~~~
llm_build/8a16399c-2874-11f0-8ad6-e10f5b0b7eea/Solution.cpp:23:34: error: conversion from ‘time_point<[...],duration<[...],ratio<54,[...]>>>’ to non-scalar type ‘time_point<[...],duration<[...],ratio<86400,[...]>>>’ requested
   23 |     sys_days a_month_ago = today - months{1};
      |                            ~~~~~~^~~~~~~~~~~
Traceback (most recent call last):
  File "/home/doyle/Documents/COS484/COS484_PAL/.venv/lib/python3.10/site-packages/pal/core/interface.py", line 185, in run
    exec_result = self.execute(code)
  File "/home/doyle/Documents/COS484/COS484_PAL/.venv/lib/python3.10/site-packages/pal/core/interface.py", line 114, in execute
    self.runtime.exec_code('\n'.join(code))
  File "/home/doyle/Documents/COS484/COS484_PAL/.venv/lib/python3.10/site-packages/pal/core/runtime.py", line 206, in exec_code
    result = subprocess.run([f"llm_build/{str(random_uuid)}/Solution"], capture_output=True)
  File "/usr/lib/python3.10/subprocess.py", line 503, in run
    with Popen(*popenargs, **kwargs) as process:
  File "/usr/lib/python3.10/subprocess.py", line 971, in __init__
    self._execute_child(args, executable, preexec_fn, close_fds,
  File "/usr/lib/python3.10/subprocess.py", line 1863, in _execute_child
    raise child_exception_type(errno_num, err_msg, err_filename)
FileNotFoundError: [Errno 2] No such file or directory: 'llm_build/400fc12e-2874-11f0-8ad4-e10f5b0b7eea/Solution'

Execute error: 
Traceback (most recent call last):
  File "/home/doyle/Documents/COS484/COS484_PAL/.venv/lib/python3.10/site-packages/pal/core/interface.py", line 185, in run
    exec_result = self.execute(code)
  File "/home/doyle/Documents/COS484/COS484_PAL/.venv/lib/python3.10/site-packages/pal/core/interface.py", line 114, in execute
    self.runtime.exec_code('\n'.join(code))
  File "/home/doyle/Documents/COS484/COS484_PAL/.venv/lib/python3.10/site-packages/pal/core/runtime.py", line 206, in exec_code
    result = subprocess.run([f"llm_build/{str(random_uuid)}/Solution"], capture_output=True)
  File "/usr/lib/python3.10/subprocess.py", line 503, in run
    with Popen(*popenargs, **kwargs) as process:
  File "/usr/lib/python3.10/subprocess.py", line 971, in __init__
    self._execute_child(args, executable, preexec_fn, close_fds,
  File "/usr/lib/python3.10/subprocess.py", line 1863, in _execute_child
    raise child_exception_type(errno_num, err_msg, err_filename)
FileNotFoundError: [Errno 2] No such file or directory: 'llm_build/417a66fe-2874-11f0-8ad4-e10f5b0b7eea/Solution'

Execute error: 
Traceback (most recent call last):
  File "/home/doyle/Documents/COS484/COS484_PAL/.venv/lib/python3.10/site-packages/pal/core/interface.py", line 185, in run
    exec_result = self.execute(code)
  File "/home/doyle/Documents/COS484/COS484_PAL/.venv/lib/python3.10/site-packages/pal/core/interface.py", line 114, in execute
    self.runtime.exec_code('\n'.join(code))
  File "/home/doyle/Documents/COS484/COS484_PAL/.venv/lib/python3.10/site-packages/pal/core/runtime.py", line 206, in exec_code
    result = subprocess.run([f"llm_build/{str(random_uuid)}/Solution"], capture_output=True)
  File "/usr/lib/python3.10/subprocess.py", line 503, in run
    with Popen(*popenargs, **kwargs) as process:
  File "/usr/lib/python3.10/subprocess.py", line 971, in __init__
    self._execute_child(args, executable, preexec_fn, close_fds,
  File "/usr/lib/python3.10/subprocess.py", line 1863, in _execute_child
    raise child_exception_type(errno_num, err_msg, err_filename)
FileNotFoundError: [Errno 2] No such file or directory: 'llm_build/63eea29a-2874-11f0-8ad4-e10f5b0b7eea/Solution'

Execute error: 
Traceback (most recent call last):
  File "/home/doyle/Documents/COS484/COS484_PAL/.venv/lib/python3.10/site-packages/pal/core/interface.py", line 185, in run
    exec_result = self.execute(code)
  File "/home/doyle/Documents/COS484/COS484_PAL/.venv/lib/python3.10/site-packages/pal/core/interface.py", line 114, in execute
    self.runtime.exec_code('\n'.join(code))
  File "/home/doyle/Documents/COS484/COS484_PAL/.venv/lib/python3.10/site-packages/pal/core/runtime.py", line 206, in exec_code
    result = subprocess.run([f"llm_build/{str(random_uuid)}/Solution"], capture_output=True)
  File "/usr/lib/python3.10/subprocess.py", line 503, in run
    with Popen(*popenargs, **kwargs) as process:
  File "/usr/lib/python3.10/subprocess.py", line 971, in __init__
    self._execute_child(args, executable, preexec_fn, close_fds,
  File "/usr/lib/python3.10/subprocess.py", line 1863, in _execute_child
    raise child_exception_type(errno_num, err_msg, err_filename)
FileNotFoundError: [Errno 2] No such file or directory: 'llm_build/655ae4ea-2874-11f0-8ad5-e10f5b0b7eea/Solution'

Execute error: 
Traceback (most recent call last):
  File "/home/doyle/Documents/COS484/COS484_PAL/.venv/lib/python3.10/site-packages/pal/core/interface.py", line 185, in run
    exec_result = self.execute(code)
  File "/home/doyle/Documents/COS484/COS484_PAL/.venv/lib/python3.10/site-packages/pal/core/interface.py", line 114, in execute
    self.runtime.exec_code('\n'.join(code))
  File "/home/doyle/Documents/COS484/COS484_PAL/.venv/lib/python3.10/site-packages/pal/core/runtime.py", line 206, in exec_code
    result = subprocess.run([f"llm_build/{str(random_uuid)}/Solution"], capture_output=True)
  File "/usr/lib/python3.10/subprocess.py", line 503, in run
    with Popen(*popenargs, **kwargs) as process:
  File "/usr/lib/python3.10/subprocess.py", line 971, in __init__
    self._execute_child(args, executable, preexec_fn, close_fds,
  File "/usr/lib/python3.10/subprocess.py", line 1863, in _execute_child
    raise child_exception_type(errno_num, err_msg, err_filename)
FileNotFoundError: [Errno 2] No such file or directory: 'llm_build/69915a08-2874-11f0-8ad5-e10f5b0b7eea/Solution'

Execute error: 
Traceback (most recent call last):
  File "/home/doyle/Documents/COS484/COS484_PAL/.venv/lib/python3.10/site-packages/pal/core/interface.py", line 185, in run
    exec_result = self.execute(code)
  File "/home/doyle/Documents/COS484/COS484_PAL/.venv/lib/python3.10/site-packages/pal/core/interface.py", line 114, in execute
    self.runtime.exec_code('\n'.join(code))
  File "/home/doyle/Documents/COS484/COS484_PAL/.venv/lib/python3.10/site-packages/pal/core/runtime.py", line 206, in exec_code
    result = subprocess.run([f"llm_build/{str(random_uuid)}/Solution"], capture_output=True)
  File "/usr/lib/python3.10/subprocess.py", line 503, in run
    with Popen(*popenargs, **kwargs) as process:
  File "/usr/lib/python3.10/subprocess.py", line 971, in __init__
    self._execute_child(args, executable, preexec_fn, close_fds,
  File "/usr/lib/python3.10/subprocess.py", line 1863, in _execute_child
    raise child_exception_type(errno_num, err_msg, err_filename)
FileNotFoundError: [Errno 2] No such file or directory: 'llm_build/7dee4164-2874-11f0-8ad5-e10f5b0b7eea/Solution'

Execute error: 
Traceback (most recent call last):
  File "/home/doyle/Documents/COS484/COS484_PAL/.venv/lib/python3.10/site-packages/pal/core/interface.py", line 185, in run
    exec_result = self.execute(code)
  File "/home/doyle/Documents/COS484/COS484_PAL/.venv/lib/python3.10/site-packages/pal/core/interface.py", line 114, in execute
    self.runtime.exec_code('\n'.join(code))
  File "/home/doyle/Documents/COS484/COS484_PAL/.venv/lib/python3.10/site-packages/pal/core/runtime.py", line 206, in exec_code
    result = subprocess.run([f"llm_build/{str(random_uuid)}/Solution"], capture_output=True)
  File "/usr/lib/python3.10/subprocess.py", line 503, in run
    with Popen(*popenargs, **kwargs) as process:
  File "/usr/lib/python3.10/subprocess.py", line 971, in __init__
    self._execute_child(args, executable, preexec_fn, close_fds,
  File "/usr/lib/python3.10/subprocess.py", line 1863, in _execute_child
    raise child_exception_type(errno_num, err_msg, err_filename)
FileNotFoundError: [Errno 2] No such file or directory: 'llm_build/87af70a6-2874-11f0-8ad6-e10f5b0b7eea/Solution'

Execute error: 
 21%|██        | 77/369 [19:28<1:01:39, 12.67s/it]llm_build/8b61d068-2874-11f0-8ad6-e10f5b0b7eea/Solution.cpp: In function ‘int main()’:
llm_build/8b61d068-2874-11f0-8ad6-e10f5b0b7eea/Solution.cpp:20:35: error: conversion from ‘time_point<[...],duration<[...],ratio<216,[...]>>>’ to non-scalar type ‘time_point<[...],duration<[...],ratio<86400,[...]>>>’ requested
   20 |     sys_days today = wedding_date + years{50};
      |                      ~~~~~~~~~~~~~^~~~~~~~~~~
llm_build/8b61d068-2874-11f0-8ad6-e10f5b0b7eea/Solution.cpp:23:35: error: conversion from ‘time_point<[...],duration<[...],ratio<216,[...]>>>’ to non-scalar type ‘time_point<[...],duration<[...],ratio<86400,[...]>>>’ requested
   23 |     sys_days one_year_ago = today - years{1};
      |                             ~~~~~~^~~~~~~~~~
 21%|██        | 78/369 [19:30<46:09,  9.52s/it]  llm_build/a2140a74-2874-11f0-8ad6-e10f5b0b7eea/Solution.cpp: In function ‘int main()’:
llm_build/a2140a74-2874-11f0-8ad6-e10f5b0b7eea/Solution.cpp:20:35: error: conversion from ‘time_point<[...],duration<[...],ratio<216,[...]>>>’ to non-scalar type ‘time_point<[...],duration<[...],ratio<86400,[...]>>>’ requested
   20 |     sys_days today = wedding_date + years{50};
      |                      ~~~~~~~~~~~~~^~~~~~~~~~~
 21%|██▏       | 79/369 [20:08<1:27:22, 18.08s/it]llm_build/a90df772-2874-11f0-8ad6-e10f5b0b7eea/Solution.cpp: In function ‘int main()’:
llm_build/a90df772-2874-11f0-8ad6-e10f5b0b7eea/Solution.cpp:20:35: error: conversion from ‘time_point<[...],duration<[...],ratio<216,[...]>>>’ to non-scalar type ‘time_point<[...],duration<[...],ratio<86400,[...]>>>’ requested
   20 |     sys_days today = wedding_date + years{50};
      |                      ~~~~~~~~~~~~~^~~~~~~~~~~
 22%|██▏       | 80/369 [20:20<1:17:55, 16.18s/it]llm_build/aaff1a52-2874-11f0-8ad6-e10f5b0b7eea/Solution.cpp: In function ‘int main()’:
llm_build/aaff1a52-2874-11f0-8ad6-e10f5b0b7eea/Solution.cpp:20:35: error: conversion from ‘time_point<[...],duration<[...],ratio<216,[...]>>>’ to non-scalar type ‘time_point<[...],duration<[...],ratio<86400,[...]>>>’ requested
   20 |     sys_days today = wedding_date + years{50};
      |                      ~~~~~~~~~~~~~^~~~~~~~~~~
 22%|██▏       | 81/369 [20:23<59:01, 12.30s/it]  llm_build/ad857c08-2874-11f0-8ad6-e10f5b0b7eea/Solution.cpp: In function ‘int main()’:
llm_build/ad857c08-2874-11f0-8ad6-e10f5b0b7eea/Solution.cpp:20:33: error: conversion from ‘time_point<[...],duration<[...],ratio<216,[...]>>>’ to non-scalar type ‘time_point<[...],duration<[...],ratio<86400,[...]>>>’ requested
   20 |     sys_days today = start_date + years{3};
      |                      ~~~~~~~~~~~^~~~~~~~~~
 22%|██▏       | 82/369 [20:28<47:17,  9.89s/it]llm_build/aed6e8ee-2874-11f0-8ad6-e10f5b0b7eea/Solution.cpp: In function ‘int main()’:
llm_build/aed6e8ee-2874-11f0-8ad6-e10f5b0b7eea/Solution.cpp:20:33: error: conversion from ‘time_point<[...],duration<[...],ratio<216,[...]>>>’ to non-scalar type ‘time_point<[...],duration<[...],ratio<86400,[...]>>>’ requested
   20 |     sys_days today = start_date + years{3};
      |                      ~~~~~~~~~~~^~~~~~~~~~
 22%|██▏       | 83/369 [20:30<36:07,  7.58s/it]llm_build/b03c7dc0-2874-11f0-8ad6-e10f5b0b7eea/Solution.cpp: In function ‘int main()’:
llm_build/b03c7dc0-2874-11f0-8ad6-e10f5b0b7eea/Solution.cpp:20:33: error: conversion from ‘time_point<[...],duration<[...],ratio<216,[...]>>>’ to non-scalar type ‘time_point<[...],duration<[...],ratio<86400,[...]>>>’ requested
   20 |     sys_days today = start_date + years{3};
      |                      ~~~~~~~~~~~^~~~~~~~~~
Traceback (most recent call last):
  File "/home/doyle/Documents/COS484/COS484_PAL/.venv/lib/python3.10/site-packages/pal/core/interface.py", line 185, in run
    exec_result = self.execute(code)
  File "/home/doyle/Documents/COS484/COS484_PAL/.venv/lib/python3.10/site-packages/pal/core/interface.py", line 114, in execute
    self.runtime.exec_code('\n'.join(code))
  File "/home/doyle/Documents/COS484/COS484_PAL/.venv/lib/python3.10/site-packages/pal/core/runtime.py", line 206, in exec_code
    result = subprocess.run([f"llm_build/{str(random_uuid)}/Solution"], capture_output=True)
  File "/usr/lib/python3.10/subprocess.py", line 503, in run
    with Popen(*popenargs, **kwargs) as process:
  File "/usr/lib/python3.10/subprocess.py", line 971, in __init__
    self._execute_child(args, executable, preexec_fn, close_fds,
  File "/usr/lib/python3.10/subprocess.py", line 1863, in _execute_child
    raise child_exception_type(errno_num, err_msg, err_filename)
FileNotFoundError: [Errno 2] No such file or directory: 'llm_build/8a16399c-2874-11f0-8ad6-e10f5b0b7eea/Solution'

Execute error: 
Traceback (most recent call last):
  File "/home/doyle/Documents/COS484/COS484_PAL/.venv/lib/python3.10/site-packages/pal/core/interface.py", line 185, in run
    exec_result = self.execute(code)
  File "/home/doyle/Documents/COS484/COS484_PAL/.venv/lib/python3.10/site-packages/pal/core/interface.py", line 114, in execute
    self.runtime.exec_code('\n'.join(code))
  File "/home/doyle/Documents/COS484/COS484_PAL/.venv/lib/python3.10/site-packages/pal/core/runtime.py", line 206, in exec_code
    result = subprocess.run([f"llm_build/{str(random_uuid)}/Solution"], capture_output=True)
  File "/usr/lib/python3.10/subprocess.py", line 503, in run
    with Popen(*popenargs, **kwargs) as process:
  File "/usr/lib/python3.10/subprocess.py", line 971, in __init__
    self._execute_child(args, executable, preexec_fn, close_fds,
  File "/usr/lib/python3.10/subprocess.py", line 1863, in _execute_child
    raise child_exception_type(errno_num, err_msg, err_filename)
FileNotFoundError: [Errno 2] No such file or directory: 'llm_build/8b61d068-2874-11f0-8ad6-e10f5b0b7eea/Solution'

Execute error: 
Traceback (most recent call last):
  File "/home/doyle/Documents/COS484/COS484_PAL/.venv/lib/python3.10/site-packages/pal/core/interface.py", line 185, in run
    exec_result = self.execute(code)
  File "/home/doyle/Documents/COS484/COS484_PAL/.venv/lib/python3.10/site-packages/pal/core/interface.py", line 114, in execute
    self.runtime.exec_code('\n'.join(code))
  File "/home/doyle/Documents/COS484/COS484_PAL/.venv/lib/python3.10/site-packages/pal/core/runtime.py", line 206, in exec_code
    result = subprocess.run([f"llm_build/{str(random_uuid)}/Solution"], capture_output=True)
  File "/usr/lib/python3.10/subprocess.py", line 503, in run
    with Popen(*popenargs, **kwargs) as process:
  File "/usr/lib/python3.10/subprocess.py", line 971, in __init__
    self._execute_child(args, executable, preexec_fn, close_fds,
  File "/usr/lib/python3.10/subprocess.py", line 1863, in _execute_child
    raise child_exception_type(errno_num, err_msg, err_filename)
FileNotFoundError: [Errno 2] No such file or directory: 'llm_build/a2140a74-2874-11f0-8ad6-e10f5b0b7eea/Solution'

Execute error: 
Traceback (most recent call last):
  File "/home/doyle/Documents/COS484/COS484_PAL/.venv/lib/python3.10/site-packages/pal/core/interface.py", line 185, in run
    exec_result = self.execute(code)
  File "/home/doyle/Documents/COS484/COS484_PAL/.venv/lib/python3.10/site-packages/pal/core/interface.py", line 114, in execute
    self.runtime.exec_code('\n'.join(code))
  File "/home/doyle/Documents/COS484/COS484_PAL/.venv/lib/python3.10/site-packages/pal/core/runtime.py", line 206, in exec_code
    result = subprocess.run([f"llm_build/{str(random_uuid)}/Solution"], capture_output=True)
  File "/usr/lib/python3.10/subprocess.py", line 503, in run
    with Popen(*popenargs, **kwargs) as process:
  File "/usr/lib/python3.10/subprocess.py", line 971, in __init__
    self._execute_child(args, executable, preexec_fn, close_fds,
  File "/usr/lib/python3.10/subprocess.py", line 1863, in _execute_child
    raise child_exception_type(errno_num, err_msg, err_filename)
FileNotFoundError: [Errno 2] No such file or directory: 'llm_build/a90df772-2874-11f0-8ad6-e10f5b0b7eea/Solution'

Execute error: 
Traceback (most recent call last):
  File "/home/doyle/Documents/COS484/COS484_PAL/.venv/lib/python3.10/site-packages/pal/core/interface.py", line 185, in run
    exec_result = self.execute(code)
  File "/home/doyle/Documents/COS484/COS484_PAL/.venv/lib/python3.10/site-packages/pal/core/interface.py", line 114, in execute
    self.runtime.exec_code('\n'.join(code))
  File "/home/doyle/Documents/COS484/COS484_PAL/.venv/lib/python3.10/site-packages/pal/core/runtime.py", line 206, in exec_code
    result = subprocess.run([f"llm_build/{str(random_uuid)}/Solution"], capture_output=True)
  File "/usr/lib/python3.10/subprocess.py", line 503, in run
    with Popen(*popenargs, **kwargs) as process:
  File "/usr/lib/python3.10/subprocess.py", line 971, in __init__
    self._execute_child(args, executable, preexec_fn, close_fds,
  File "/usr/lib/python3.10/subprocess.py", line 1863, in _execute_child
    raise child_exception_type(errno_num, err_msg, err_filename)
FileNotFoundError: [Errno 2] No such file or directory: 'llm_build/aaff1a52-2874-11f0-8ad6-e10f5b0b7eea/Solution'

Execute error: 
Traceback (most recent call last):
  File "/home/doyle/Documents/COS484/COS484_PAL/.venv/lib/python3.10/site-packages/pal/core/interface.py", line 185, in run
    exec_result = self.execute(code)
  File "/home/doyle/Documents/COS484/COS484_PAL/.venv/lib/python3.10/site-packages/pal/core/interface.py", line 114, in execute
    self.runtime.exec_code('\n'.join(code))
  File "/home/doyle/Documents/COS484/COS484_PAL/.venv/lib/python3.10/site-packages/pal/core/runtime.py", line 206, in exec_code
    result = subprocess.run([f"llm_build/{str(random_uuid)}/Solution"], capture_output=True)
  File "/usr/lib/python3.10/subprocess.py", line 503, in run
    with Popen(*popenargs, **kwargs) as process:
  File "/usr/lib/python3.10/subprocess.py", line 971, in __init__
    self._execute_child(args, executable, preexec_fn, close_fds,
  File "/usr/lib/python3.10/subprocess.py", line 1863, in _execute_child
    raise child_exception_type(errno_num, err_msg, err_filename)
FileNotFoundError: [Errno 2] No such file or directory: 'llm_build/ad857c08-2874-11f0-8ad6-e10f5b0b7eea/Solution'

Execute error: 
Traceback (most recent call last):
  File "/home/doyle/Documents/COS484/COS484_PAL/.venv/lib/python3.10/site-packages/pal/core/interface.py", line 185, in run
    exec_result = self.execute(code)
  File "/home/doyle/Documents/COS484/COS484_PAL/.venv/lib/python3.10/site-packages/pal/core/interface.py", line 114, in execute
    self.runtime.exec_code('\n'.join(code))
  File "/home/doyle/Documents/COS484/COS484_PAL/.venv/lib/python3.10/site-packages/pal/core/runtime.py", line 206, in exec_code
    result = subprocess.run([f"llm_build/{str(random_uuid)}/Solution"], capture_output=True)
  File "/usr/lib/python3.10/subprocess.py", line 503, in run
    with Popen(*popenargs, **kwargs) as process:
  File "/usr/lib/python3.10/subprocess.py", line 971, in __init__
    self._execute_child(args, executable, preexec_fn, close_fds,
  File "/usr/lib/python3.10/subprocess.py", line 1863, in _execute_child
    raise child_exception_type(errno_num, err_msg, err_filename)
FileNotFoundError: [Errno 2] No such file or directory: 'llm_build/aed6e8ee-2874-11f0-8ad6-e10f5b0b7eea/Solution'

Execute error: 
 23%|██▎       | 84/369 [20:32<28:30,  6.00s/it] 23%|██▎       | 85/369 [21:10<1:12:53, 15.40s/it] 23%|██▎       | 86/369 [21:24<1:11:21, 15.13s/it]llm_build/d28b0c84-2874-11f0-8ad6-e10f5b0b7eea/Solution.cpp: In function ‘int main()’:
llm_build/d28b0c84-2874-11f0-8ad6-e10f5b0b7eea/Solution.cpp:20:33: error: conversion from ‘time_point<[...],duration<[...],ratio<216,[...]>>>’ to non-scalar type ‘time_point<[...],duration<[...],ratio<86400,[...]>>>’ requested
   20 |     sys_days today = start_date + years{3};
      |                      ~~~~~~~~~~~^~~~~~~~~~
llm_build/d28b0c84-2874-11f0-8ad6-e10f5b0b7eea/Solution.cpp:23:35: error: conversion from ‘time_point<[...],duration<[...],ratio<216,[...]>>>’ to non-scalar type ‘time_point<[...],duration<[...],ratio<86400,[...]>>>’ requested
   23 |     sys_days one_year_ago = today - years{1};
      |                             ~~~~~~^~~~~~~~~~
 24%|██▎       | 87/369 [21:30<57:57, 12.33s/it]  llm_build/f146f584-2874-11f0-8ad6-e10f5b0b7eea/Solution.cpp: In function ‘int main()’:
llm_build/f146f584-2874-11f0-8ad6-e10f5b0b7eea/Solution.cpp:20:33: error: conversion from ‘time_point<[...],duration<[...],ratio<216,[...]>>>’ to non-scalar type ‘time_point<[...],duration<[...],ratio<86400,[...]>>>’ requested
   20 |     sys_days today = start_date + years{3};
      |                      ~~~~~~~~~~~^~~~~~~~~~
 24%|██▍       | 88/369 [22:21<1:52:44, 24.07s/it] 24%|██▍       | 89/369 [22:24<1:22:15, 17.63s/it]llm_build/f44773d0-2874-11f0-8ad7-e10f5b0b7eea/Solution.cpp: In function ‘int main()’:
llm_build/f44773d0-2874-11f0-8ad7-e10f5b0b7eea/Solution.cpp:20:33: error: conversion from ‘time_point<[...],duration<[...],ratio<216,[...]>>>’ to non-scalar type ‘time_point<[...],duration<[...],ratio<86400,[...]>>>’ requested
   20 |     sys_days today = start_date + years{3};
      |                      ~~~~~~~~~~~^~~~~~~~~~
 24%|██▍       | 90/369 [22:26<1:00:53, 13.10s/it] 25%|██▍       | 91/369 [22:29<46:31, 10.04s/it]   25%|██▍       | 92/369 [22:31<35:16,  7.64s/it] 25%|██▌       | 93/369 [22:34<27:46,  6.04s/it] 25%|██▌       | 94/369 [23:10<1:09:15, 15.11s/it]llm_build/15854388-2875-11f0-8ad7-e10f5b0b7eea/Solution.cpp: In function ‘int main()’:
llm_build/15854388-2875-11f0-8ad7-e10f5b0b7eea/Solution.cpp:23:34: error: conversion from ‘time_point<[...],duration<[...],ratio<54,[...]>>>’ to non-scalar type ‘time_point<[...],duration<[...],ratio<86400,[...]>>>’ requested
   23 |     sys_days a_month_ago = today - months{1};
      |                            ~~~~~~^~~~~~~~~~~
 26%|██▌       | 95/369 [23:22<1:05:03, 14.25s/it] 26%|██▌       | 96/369 [23:25<48:59, 10.77s/it]   26%|██▋       | 97/369 [23:28<38:17,  8.44s/it] 27%|██▋       | 98/369 [23:30<30:08,  6.68s/it] 27%|██▋       | 99/369 [23:33<24:39,  5.48s/it] 27%|██▋       | 100/369 [24:28<1:30:58, 20.29s/it] 27%|██▋       | 101/369 [24:30<1:06:11, 14.82s/it] 28%|██▊       | 102/369 [24:32<49:03, 11.03s/it]   28%|██▊       | 103/369 [24:35<37:19,  8.42s/it] 28%|██▊       | 104/369 [25:30<1:39:47, 22.59s/it] 28%|██▊       | 105/369 [25:34<1:14:14, 16.87s/it] 29%|██▊       | 106/369 [25:36<54:51, 12.52s/it]   29%|██▉       | 107/369 [26:31<1:50:00, 25.19s/it] 29%|██▉       | 108/369 [26:35<1:22:36, 18.99s/it] 30%|██▉       | 109/369 [26:39<1:01:58, 14.30s/it] 30%|██▉       | 110/369 [27:11<1:25:32, 19.81s/it] 30%|███       | 111/369 [27:16<1:05:32, 15.24s/it] 30%|███       | 112/369 [27:33<1:07:46, 15.82s/it] 31%|███       | 113/369 [27:35<50:02, 11.73s/it]   31%|███       | 114/369 [27:40<41:01,  9.65s/it] 31%|███       | 115/369 [28:27<1:27:42, 20.72s/it] 31%|███▏      | 116/369 [28:29<1:04:26, 15.28s/it] 32%|███▏      | 117/369 [28:38<56:03, 13.35s/it]   32%|███▏      | 118/369 [28:41<42:36, 10.19s/it] 32%|███▏      | 119/369 [29:13<1:10:03, 16.82s/it] 33%|███▎      | 120/369 [29:23<1:00:33, 14.59s/it] 33%|███▎      | 121/369 [29:34<56:34, 13.69s/it]   33%|███▎      | 122/369 [29:38<43:45, 10.63s/it] 33%|███▎      | 123/369 [29:40<33:38,  8.21s/it] 34%|███▎      | 124/369 [29:44<27:50,  6.82s/it] 34%|███▍      | 125/369 [30:12<54:04, 13.30s/it] 34%|███▍      | 126/369 [30:35<1:05:08, 16.08s/it] 34%|███▍      | 127/369 [30:38<48:44, 12.08s/it]   35%|███▍      | 128/369 [30:40<37:25,  9.32s/it] 35%|███▍      | 129/369 [30:43<29:23,  7.35s/it] 35%|███▌      | 130/369 [31:14<56:45, 14.25s/it]llm_build/34193574-2876-11f0-8adc-e10f5b0b7eea/Solution.cpp: In function ‘int main()’:
llm_build/34193574-2876-11f0-8adc-e10f5b0b7eea/Solution.cpp:23:34: error: conversion from ‘time_point<[...],duration<[...],ratio<54,[...]>>>’ to non-scalar type ‘time_point<[...],duration<[...],ratio<86400,[...]>>>’ requested
   23 |     sys_days a_month_ago = today - months{1};
      |                            ~~~~~~^~~~~~~~~~~
 36%|███▌      | 131/369 [31:23<50:51, 12.82s/it]llm_build/3bf6027c-2876-11f0-8adc-e10f5b0b7eea/Solution.cpp: In function ‘int main()’:
llm_build/3bf6027c-2876-11f0-8adc-e10f5b0b7eea/Solution.cpp:23:35: error: conversion from ‘time_point<[...],duration<[...],ratio<216,[...]>>>’ to non-scalar type ‘time_point<[...],duration<[...],ratio<86400,[...]>>>’ requested
   23 |     sys_days one_year_ago = today - years{1};
      |                             ~~~~~~^~~~~~~~~~
 36%|███▌      | 132/369 [31:36<51:22, 13.01s/it] 36%|███▌      | 133/369 [31:39<39:16,  9.98s/it] 36%|███▋      | 134/369 [31:42<30:27,  7.78s/it] 37%|███▋      | 135/369 [31:44<24:00,  6.15s/it] 37%|███▋      | 136/369 [31:47<19:56,  5.14s/it] 37%|███▋      | 137/369 [32:15<46:13, 11.95s/it] 37%|███▋      | 138/369 [32:24<42:06, 10.94s/it] 38%|███▊      | 139/369 [32:36<43:36, 11.37s/it] 38%|███▊      | 140/369 [32:38<33:07,  8.68s/it] 38%|███▊      | 141/369 [32:42<27:46,  7.31s/it] 38%|███▊      | 142/369 [32:45<22:08,  5.85s/it] 39%|███▉      | 143/369 [32:48<18:29,  4.91s/it] 39%|███▉      | 144/369 [33:15<43:54, 11.71s/it] 39%|███▉      | 145/369 [33:23<39:32, 10.59s/it] 40%|███▉      | 146/369 [33:37<42:30, 11.44s/it] 40%|███▉      | 147/369 [33:41<34:01,  9.20s/it] 40%|████      | 148/369 [33:45<28:25,  7.72s/it] 40%|████      | 149/369 [33:48<22:43,  6.20s/it]llm_build/8b80b6de-2876-11f0-8adc-e10f5b0b7eea/Solution.cpp: In function ‘int main()’:
llm_build/8b80b6de-2876-11f0-8adc-e10f5b0b7eea/Solution.cpp:18:35: error: conversion from ‘time_point<[...],duration<[...],ratio<216,[...]>>>’ to non-scalar type ‘time_point<[...],duration<[...],ratio<86400,[...]>>>’ requested
   18 |     sys_days one_year_ago = today - years{1};
      |                             ~~~~~~^~~~~~~~~~
Traceback (most recent call last):
  File "/home/doyle/Documents/COS484/COS484_PAL/.venv/lib/python3.10/site-packages/pal/core/interface.py", line 185, in run
    exec_result = self.execute(code)
  File "/home/doyle/Documents/COS484/COS484_PAL/.venv/lib/python3.10/site-packages/pal/core/interface.py", line 114, in execute
    self.runtime.exec_code('\n'.join(code))
  File "/home/doyle/Documents/COS484/COS484_PAL/.venv/lib/python3.10/site-packages/pal/core/runtime.py", line 206, in exec_code
    result = subprocess.run([f"llm_build/{str(random_uuid)}/Solution"], capture_output=True)
  File "/usr/lib/python3.10/subprocess.py", line 503, in run
    with Popen(*popenargs, **kwargs) as process:
  File "/usr/lib/python3.10/subprocess.py", line 971, in __init__
    self._execute_child(args, executable, preexec_fn, close_fds,
  File "/usr/lib/python3.10/subprocess.py", line 1863, in _execute_child
    raise child_exception_type(errno_num, err_msg, err_filename)
FileNotFoundError: [Errno 2] No such file or directory: 'llm_build/b03c7dc0-2874-11f0-8ad6-e10f5b0b7eea/Solution'

Execute error: 
Traceback (most recent call last):
  File "/home/doyle/Documents/COS484/COS484_PAL/.venv/lib/python3.10/site-packages/pal/core/interface.py", line 185, in run
    exec_result = self.execute(code)
  File "/home/doyle/Documents/COS484/COS484_PAL/.venv/lib/python3.10/site-packages/pal/core/interface.py", line 114, in execute
    self.runtime.exec_code('\n'.join(code))
  File "/home/doyle/Documents/COS484/COS484_PAL/.venv/lib/python3.10/site-packages/pal/core/runtime.py", line 206, in exec_code
    result = subprocess.run([f"llm_build/{str(random_uuid)}/Solution"], capture_output=True)
  File "/usr/lib/python3.10/subprocess.py", line 503, in run
    with Popen(*popenargs, **kwargs) as process:
  File "/usr/lib/python3.10/subprocess.py", line 971, in __init__
    self._execute_child(args, executable, preexec_fn, close_fds,
  File "/usr/lib/python3.10/subprocess.py", line 1863, in _execute_child
    raise child_exception_type(errno_num, err_msg, err_filename)
FileNotFoundError: [Errno 2] No such file or directory: 'llm_build/d28b0c84-2874-11f0-8ad6-e10f5b0b7eea/Solution'

Execute error: 
Traceback (most recent call last):
  File "/home/doyle/Documents/COS484/COS484_PAL/.venv/lib/python3.10/site-packages/pal/core/interface.py", line 185, in run
    exec_result = self.execute(code)
  File "/home/doyle/Documents/COS484/COS484_PAL/.venv/lib/python3.10/site-packages/pal/core/interface.py", line 114, in execute
    self.runtime.exec_code('\n'.join(code))
  File "/home/doyle/Documents/COS484/COS484_PAL/.venv/lib/python3.10/site-packages/pal/core/runtime.py", line 206, in exec_code
    result = subprocess.run([f"llm_build/{str(random_uuid)}/Solution"], capture_output=True)
  File "/usr/lib/python3.10/subprocess.py", line 503, in run
    with Popen(*popenargs, **kwargs) as process:
  File "/usr/lib/python3.10/subprocess.py", line 971, in __init__
    self._execute_child(args, executable, preexec_fn, close_fds,
  File "/usr/lib/python3.10/subprocess.py", line 1863, in _execute_child
    raise child_exception_type(errno_num, err_msg, err_filename)
FileNotFoundError: [Errno 2] No such file or directory: 'llm_build/f146f584-2874-11f0-8ad6-e10f5b0b7eea/Solution'

Execute error: 
Traceback (most recent call last):
  File "/home/doyle/Documents/COS484/COS484_PAL/.venv/lib/python3.10/site-packages/pal/core/interface.py", line 185, in run
    exec_result = self.execute(code)
  File "/home/doyle/Documents/COS484/COS484_PAL/.venv/lib/python3.10/site-packages/pal/core/interface.py", line 114, in execute
    self.runtime.exec_code('\n'.join(code))
  File "/home/doyle/Documents/COS484/COS484_PAL/.venv/lib/python3.10/site-packages/pal/core/runtime.py", line 206, in exec_code
    result = subprocess.run([f"llm_build/{str(random_uuid)}/Solution"], capture_output=True)
  File "/usr/lib/python3.10/subprocess.py", line 503, in run
    with Popen(*popenargs, **kwargs) as process:
  File "/usr/lib/python3.10/subprocess.py", line 971, in __init__
    self._execute_child(args, executable, preexec_fn, close_fds,
  File "/usr/lib/python3.10/subprocess.py", line 1863, in _execute_child
    raise child_exception_type(errno_num, err_msg, err_filename)
FileNotFoundError: [Errno 2] No such file or directory: 'llm_build/f44773d0-2874-11f0-8ad7-e10f5b0b7eea/Solution'

Execute error: 
Traceback (most recent call last):
  File "/home/doyle/Documents/COS484/COS484_PAL/.venv/lib/python3.10/site-packages/pal/core/interface.py", line 185, in run
    exec_result = self.execute(code)
  File "/home/doyle/Documents/COS484/COS484_PAL/.venv/lib/python3.10/site-packages/pal/core/interface.py", line 114, in execute
    self.runtime.exec_code('\n'.join(code))
  File "/home/doyle/Documents/COS484/COS484_PAL/.venv/lib/python3.10/site-packages/pal/core/runtime.py", line 206, in exec_code
    result = subprocess.run([f"llm_build/{str(random_uuid)}/Solution"], capture_output=True)
  File "/usr/lib/python3.10/subprocess.py", line 503, in run
    with Popen(*popenargs, **kwargs) as process:
  File "/usr/lib/python3.10/subprocess.py", line 971, in __init__
    self._execute_child(args, executable, preexec_fn, close_fds,
  File "/usr/lib/python3.10/subprocess.py", line 1863, in _execute_child
    raise child_exception_type(errno_num, err_msg, err_filename)
FileNotFoundError: [Errno 2] No such file or directory: 'llm_build/15854388-2875-11f0-8ad7-e10f5b0b7eea/Solution'

Execute error: 
Traceback (most recent call last):
  File "/home/doyle/Documents/COS484/COS484_PAL/.venv/lib/python3.10/site-packages/pal/core/interface.py", line 185, in run
    exec_result = self.execute(code)
  File "/home/doyle/Documents/COS484/COS484_PAL/.venv/lib/python3.10/site-packages/pal/core/interface.py", line 114, in execute
    self.runtime.exec_code('\n'.join(code))
  File "/home/doyle/Documents/COS484/COS484_PAL/.venv/lib/python3.10/site-packages/pal/core/runtime.py", line 206, in exec_code
    result = subprocess.run([f"llm_build/{str(random_uuid)}/Solution"], capture_output=True)
  File "/usr/lib/python3.10/subprocess.py", line 503, in run
    with Popen(*popenargs, **kwargs) as process:
  File "/usr/lib/python3.10/subprocess.py", line 971, in __init__
    self._execute_child(args, executable, preexec_fn, close_fds,
  File "/usr/lib/python3.10/subprocess.py", line 1863, in _execute_child
    raise child_exception_type(errno_num, err_msg, err_filename)
FileNotFoundError: [Errno 2] No such file or directory: 'llm_build/34193574-2876-11f0-8adc-e10f5b0b7eea/Solution'

Execute error: 
Traceback (most recent call last):
  File "/home/doyle/Documents/COS484/COS484_PAL/.venv/lib/python3.10/site-packages/pal/core/interface.py", line 185, in run
    exec_result = self.execute(code)
  File "/home/doyle/Documents/COS484/COS484_PAL/.venv/lib/python3.10/site-packages/pal/core/interface.py", line 114, in execute
    self.runtime.exec_code('\n'.join(code))
  File "/home/doyle/Documents/COS484/COS484_PAL/.venv/lib/python3.10/site-packages/pal/core/runtime.py", line 206, in exec_code
    result = subprocess.run([f"llm_build/{str(random_uuid)}/Solution"], capture_output=True)
  File "/usr/lib/python3.10/subprocess.py", line 503, in run
    with Popen(*popenargs, **kwargs) as process:
  File "/usr/lib/python3.10/subprocess.py", line 971, in __init__
    self._execute_child(args, executable, preexec_fn, close_fds,
  File "/usr/lib/python3.10/subprocess.py", line 1863, in _execute_child
    raise child_exception_type(errno_num, err_msg, err_filename)
FileNotFoundError: [Errno 2] No such file or directory: 'llm_build/3bf6027c-2876-11f0-8adc-e10f5b0b7eea/Solution'

Execute error: 
 41%|████      | 150/369 [33:50<18:26,  5.05s/it] 41%|████      | 151/369 [34:14<39:28, 10.86s/it] 41%|████      | 152/369 [34:23<36:30, 10.09s/it] 41%|████▏     | 153/369 [34:40<43:56, 12.21s/it] 42%|████▏     | 154/369 [34:46<37:48, 10.55s/it] 42%|████▏     | 155/369 [34:49<28:50,  8.09s/it] 42%|████▏     | 156/369 [35:36<1:10:01, 19.73s/it] 43%|████▎     | 157/369 [35:38<51:23, 14.55s/it]  llm_build/cdcd2874-2876-11f0-8adc-e10f5b0b7eea/Solution.cpp: In function ‘int main()’:
llm_build/cdcd2874-2876-11f0-8adc-e10f5b0b7eea/Solution.cpp:22:34: error: conversion from ‘time_point<[...],duration<[...],ratio<54,[...]>>>’ to non-scalar type ‘time_point<[...],duration<[...],ratio<86400,[...]>>>’ requested
   22 |     sys_days a_month_ago = today - months{1};
      |                            ~~~~~~^~~~~~~~~~~
 43%|████▎     | 158/369 [35:41<39:01, 11.10s/it]llm_build/cf66f926-2876-11f0-8adc-e10f5b0b7eea/Solution.cpp: In function ‘int main()’:
llm_build/cf66f926-2876-11f0-8adc-e10f5b0b7eea/Solution.cpp:22:35: error: conversion from ‘time_point<[...],duration<[...],ratio<216,[...]>>>’ to non-scalar type ‘time_point<[...],duration<[...],ratio<86400,[...]>>>’ requested
   22 |     sys_days one_year_ago = today - years{1};
      |                             ~~~~~~^~~~~~~~~~
 43%|████▎     | 159/369 [35:44<30:02,  8.58s/it] 43%|████▎     | 160/369 [35:47<23:51,  6.85s/it] 44%|████▎     | 161/369 [35:50<20:04,  5.79s/it] 44%|████▍     | 162/369 [35:53<17:27,  5.06s/it] 44%|████▍     | 163/369 [36:43<1:03:09, 18.39s/it] 44%|████▍     | 164/369 [36:45<46:25, 13.59s/it]   45%|████▍     | 165/369 [36:50<36:57, 10.87s/it] 45%|████▍     | 166/369 [36:55<30:38,  9.06s/it] 45%|████▌     | 167/369 [37:15<42:07, 12.51s/it]llm_build/0ac5e428-2877-11f0-8adc-e10f5b0b7eea/Solution.cpp: In function ‘int main()’:
llm_build/0ac5e428-2877-11f0-8adc-e10f5b0b7eea/Solution.cpp:22:35: error: conversion from ‘time_point<[...],duration<[...],ratio<216,[...]>>>’ to non-scalar type ‘time_point<[...],duration<[...],ratio<86400,[...]>>>’ requested
   22 |     sys_days one_year_ago = today - years{1};
      |                             ~~~~~~^~~~~~~~~~
 46%|████▌     | 168/369 [37:23<37:40, 11.24s/it] 46%|████▌     | 169/369 [37:42<44:39, 13.40s/it] 46%|████▌     | 170/369 [37:46<35:02, 10.57s/it] 46%|████▋     | 171/369 [37:50<28:38,  8.68s/it] 47%|████▋     | 172/369 [37:53<23:01,  7.01s/it] 47%|████▋     | 173/369 [37:56<18:34,  5.69s/it] 47%|████▋     | 174/369 [38:17<33:08, 10.20s/it] 47%|████▋     | 175/369 [38:26<31:52,  9.86s/it] 48%|████▊     | 176/369 [38:43<38:56, 12.11s/it]llm_build/3ba7de98-2877-11f0-8add-e10f5b0b7eea/Solution.cpp: In function ‘int main()’:
llm_build/3ba7de98-2877-11f0-8add-e10f5b0b7eea/Solution.cpp:22:35: error: conversion from ‘time_point<[...],duration<[...],ratio<216,[...]>>>’ to non-scalar type ‘time_point<[...],duration<[...],ratio<86400,[...]>>>’ requested
   22 |     sys_days one_year_ago = today - years{1};
      |                             ~~~~~~^~~~~~~~~~
 48%|████▊     | 177/369 [38:45<29:30,  9.22s/it] 48%|████▊     | 178/369 [38:49<24:01,  7.55s/it] 49%|████▊     | 179/369 [38:52<19:29,  6.16s/it] 49%|████▉     | 180/369 [38:55<16:48,  5.33s/it] 49%|████▉     | 181/369 [38:58<13:48,  4.41s/it] 49%|████▉     | 182/369 [39:18<28:11,  9.04s/it] 50%|████▉     | 183/369 [39:25<26:26,  8.53s/it] 50%|████▉     | 184/369 [39:44<36:18, 11.77s/it] 50%|█████     | 185/369 [39:47<27:50,  9.08s/it]llm_build/622ff3fc-2877-11f0-8add-e10f5b0b7eea/Solution.cpp: In function ‘int main()’:
llm_build/622ff3fc-2877-11f0-8add-e10f5b0b7eea/Solution.cpp:22:35: error: conversion from ‘time_point<[...],duration<[...],ratio<216,[...]>>>’ to non-scalar type ‘time_point<[...],duration<[...],ratio<86400,[...]>>>’ requested
   22 |     sys_days one_year_ago = today - years{1};
      |                             ~~~~~~^~~~~~~~~~
 50%|█████     | 186/369 [39:50<22:13,  7.29s/it] 51%|█████     | 187/369 [39:54<18:40,  6.16s/it] 51%|█████     | 188/369 [39:57<16:19,  5.41s/it] 51%|█████     | 189/369 [40:44<53:51, 17.95s/it] 51%|█████▏    | 190/369 [40:47<39:35, 13.27s/it] 52%|█████▏    | 191/369 [40:53<33:17, 11.22s/it] 52%|█████▏    | 192/369 [40:56<25:39,  8.70s/it] 52%|█████▏    | 193/369 [40:59<20:01,  6.83s/it] 53%|█████▎    | 194/369 [41:18<31:21, 10.75s/it]llm_build/9a923318-2877-11f0-8add-e10f5b0b7eea/Solution.cpp: In function ‘int main()’:
llm_build/9a923318-2877-11f0-8add-e10f5b0b7eea/Solution.cpp:22:35: error: conversion from ‘time_point<[...],duration<[...],ratio<216,[...]>>>’ to non-scalar type ‘time_point<[...],duration<[...],ratio<86400,[...]>>>’ requested
   22 |     sys_days one_year_ago = today - years{1};
      |                             ~~~~~~^~~~~~~~~~
 53%|█████▎    | 195/369 [41:25<27:13,  9.39s/it] 53%|█████▎    | 196/369 [41:46<37:21, 12.96s/it] 53%|█████▎    | 197/369 [41:48<28:07,  9.81s/it] 54%|█████▎    | 198/369 [41:51<21:41,  7.61s/it] 54%|█████▍    | 199/369 [41:54<17:49,  6.29s/it] 54%|█████▍    | 200/369 [41:57<15:09,  5.38s/it]llm_build/b9ca7204-2877-11f0-8add-e10f5b0b7eea/Solution.cpp: In function ‘int main()’:
llm_build/b9ca7204-2877-11f0-8add-e10f5b0b7eea/Solution.cpp:23:32: error: conversion from ‘time_point<[...],duration<[...],ratio<216,[...]>>>’ to non-scalar type ‘time_point<[...],duration<[...],ratio<86400,[...]>>>’ requested
   23 |     sys_days yesterday = today - days{1};
      |                          ~~~~~~^~~~~~~~~
Traceback (most recent call last):
  File "/home/doyle/Documents/COS484/COS484_PAL/.venv/lib/python3.10/site-packages/pal/core/interface.py", line 185, in run
    exec_result = self.execute(code)
  File "/home/doyle/Documents/COS484/COS484_PAL/.venv/lib/python3.10/site-packages/pal/core/interface.py", line 114, in execute
    self.runtime.exec_code('\n'.join(code))
  File "/home/doyle/Documents/COS484/COS484_PAL/.venv/lib/python3.10/site-packages/pal/core/runtime.py", line 206, in exec_code
    result = subprocess.run([f"llm_build/{str(random_uuid)}/Solution"], capture_output=True)
  File "/usr/lib/python3.10/subprocess.py", line 503, in run
    with Popen(*popenargs, **kwargs) as process:
  File "/usr/lib/python3.10/subprocess.py", line 971, in __init__
    self._execute_child(args, executable, preexec_fn, close_fds,
  File "/usr/lib/python3.10/subprocess.py", line 1863, in _execute_child
    raise child_exception_type(errno_num, err_msg, err_filename)
FileNotFoundError: [Errno 2] No such file or directory: 'llm_build/8b80b6de-2876-11f0-8adc-e10f5b0b7eea/Solution'

Execute error: 
Traceback (most recent call last):
  File "/home/doyle/Documents/COS484/COS484_PAL/.venv/lib/python3.10/site-packages/pal/core/interface.py", line 185, in run
    exec_result = self.execute(code)
  File "/home/doyle/Documents/COS484/COS484_PAL/.venv/lib/python3.10/site-packages/pal/core/interface.py", line 114, in execute
    self.runtime.exec_code('\n'.join(code))
  File "/home/doyle/Documents/COS484/COS484_PAL/.venv/lib/python3.10/site-packages/pal/core/runtime.py", line 206, in exec_code
    result = subprocess.run([f"llm_build/{str(random_uuid)}/Solution"], capture_output=True)
  File "/usr/lib/python3.10/subprocess.py", line 503, in run
    with Popen(*popenargs, **kwargs) as process:
  File "/usr/lib/python3.10/subprocess.py", line 971, in __init__
    self._execute_child(args, executable, preexec_fn, close_fds,
  File "/usr/lib/python3.10/subprocess.py", line 1863, in _execute_child
    raise child_exception_type(errno_num, err_msg, err_filename)
FileNotFoundError: [Errno 2] No such file or directory: 'llm_build/cdcd2874-2876-11f0-8adc-e10f5b0b7eea/Solution'

Execute error: 
Traceback (most recent call last):
  File "/home/doyle/Documents/COS484/COS484_PAL/.venv/lib/python3.10/site-packages/pal/core/interface.py", line 185, in run
    exec_result = self.execute(code)
  File "/home/doyle/Documents/COS484/COS484_PAL/.venv/lib/python3.10/site-packages/pal/core/interface.py", line 114, in execute
    self.runtime.exec_code('\n'.join(code))
  File "/home/doyle/Documents/COS484/COS484_PAL/.venv/lib/python3.10/site-packages/pal/core/runtime.py", line 206, in exec_code
    result = subprocess.run([f"llm_build/{str(random_uuid)}/Solution"], capture_output=True)
  File "/usr/lib/python3.10/subprocess.py", line 503, in run
    with Popen(*popenargs, **kwargs) as process:
  File "/usr/lib/python3.10/subprocess.py", line 971, in __init__
    self._execute_child(args, executable, preexec_fn, close_fds,
  File "/usr/lib/python3.10/subprocess.py", line 1863, in _execute_child
    raise child_exception_type(errno_num, err_msg, err_filename)
FileNotFoundError: [Errno 2] No such file or directory: 'llm_build/cf66f926-2876-11f0-8adc-e10f5b0b7eea/Solution'

Execute error: 
Traceback (most recent call last):
  File "/home/doyle/Documents/COS484/COS484_PAL/.venv/lib/python3.10/site-packages/pal/core/interface.py", line 185, in run
    exec_result = self.execute(code)
  File "/home/doyle/Documents/COS484/COS484_PAL/.venv/lib/python3.10/site-packages/pal/core/interface.py", line 114, in execute
    self.runtime.exec_code('\n'.join(code))
  File "/home/doyle/Documents/COS484/COS484_PAL/.venv/lib/python3.10/site-packages/pal/core/runtime.py", line 206, in exec_code
    result = subprocess.run([f"llm_build/{str(random_uuid)}/Solution"], capture_output=True)
  File "/usr/lib/python3.10/subprocess.py", line 503, in run
    with Popen(*popenargs, **kwargs) as process:
  File "/usr/lib/python3.10/subprocess.py", line 971, in __init__
    self._execute_child(args, executable, preexec_fn, close_fds,
  File "/usr/lib/python3.10/subprocess.py", line 1863, in _execute_child
    raise child_exception_type(errno_num, err_msg, err_filename)
FileNotFoundError: [Errno 2] No such file or directory: 'llm_build/0ac5e428-2877-11f0-8adc-e10f5b0b7eea/Solution'

Execute error: 
Traceback (most recent call last):
  File "/home/doyle/Documents/COS484/COS484_PAL/.venv/lib/python3.10/site-packages/pal/core/interface.py", line 185, in run
    exec_result = self.execute(code)
  File "/home/doyle/Documents/COS484/COS484_PAL/.venv/lib/python3.10/site-packages/pal/core/interface.py", line 114, in execute
    self.runtime.exec_code('\n'.join(code))
  File "/home/doyle/Documents/COS484/COS484_PAL/.venv/lib/python3.10/site-packages/pal/core/runtime.py", line 206, in exec_code
    result = subprocess.run([f"llm_build/{str(random_uuid)}/Solution"], capture_output=True)
  File "/usr/lib/python3.10/subprocess.py", line 503, in run
    with Popen(*popenargs, **kwargs) as process:
  File "/usr/lib/python3.10/subprocess.py", line 971, in __init__
    self._execute_child(args, executable, preexec_fn, close_fds,
  File "/usr/lib/python3.10/subprocess.py", line 1863, in _execute_child
    raise child_exception_type(errno_num, err_msg, err_filename)
FileNotFoundError: [Errno 2] No such file or directory: 'llm_build/3ba7de98-2877-11f0-8add-e10f5b0b7eea/Solution'

Execute error: 
Traceback (most recent call last):
  File "/home/doyle/Documents/COS484/COS484_PAL/.venv/lib/python3.10/site-packages/pal/core/interface.py", line 185, in run
    exec_result = self.execute(code)
  File "/home/doyle/Documents/COS484/COS484_PAL/.venv/lib/python3.10/site-packages/pal/core/interface.py", line 114, in execute
    self.runtime.exec_code('\n'.join(code))
  File "/home/doyle/Documents/COS484/COS484_PAL/.venv/lib/python3.10/site-packages/pal/core/runtime.py", line 206, in exec_code
    result = subprocess.run([f"llm_build/{str(random_uuid)}/Solution"], capture_output=True)
  File "/usr/lib/python3.10/subprocess.py", line 503, in run
    with Popen(*popenargs, **kwargs) as process:
  File "/usr/lib/python3.10/subprocess.py", line 971, in __init__
    self._execute_child(args, executable, preexec_fn, close_fds,
  File "/usr/lib/python3.10/subprocess.py", line 1863, in _execute_child
    raise child_exception_type(errno_num, err_msg, err_filename)
FileNotFoundError: [Errno 2] No such file or directory: 'llm_build/622ff3fc-2877-11f0-8add-e10f5b0b7eea/Solution'

Execute error: 
Traceback (most recent call last):
  File "/home/doyle/Documents/COS484/COS484_PAL/.venv/lib/python3.10/site-packages/pal/core/interface.py", line 185, in run
    exec_result = self.execute(code)
  File "/home/doyle/Documents/COS484/COS484_PAL/.venv/lib/python3.10/site-packages/pal/core/interface.py", line 114, in execute
    self.runtime.exec_code('\n'.join(code))
  File "/home/doyle/Documents/COS484/COS484_PAL/.venv/lib/python3.10/site-packages/pal/core/runtime.py", line 206, in exec_code
    result = subprocess.run([f"llm_build/{str(random_uuid)}/Solution"], capture_output=True)
  File "/usr/lib/python3.10/subprocess.py", line 503, in run
    with Popen(*popenargs, **kwargs) as process:
  File "/usr/lib/python3.10/subprocess.py", line 971, in __init__
    self._execute_child(args, executable, preexec_fn, close_fds,
  File "/usr/lib/python3.10/subprocess.py", line 1863, in _execute_child
    raise child_exception_type(errno_num, err_msg, err_filename)
FileNotFoundError: [Errno 2] No such file or directory: 'llm_build/9a923318-2877-11f0-8add-e10f5b0b7eea/Solution'

Execute error: 
 54%|█████▍    | 201/369 [42:17<27:27,  9.80s/it] 55%|█████▍    | 202/369 [42:25<25:46,  9.26s/it]llm_build/cbd1b0d4-2877-11f0-8add-e10f5b0b7eea/Solution.cpp: In function ‘int main()’:
llm_build/cbd1b0d4-2877-11f0-8add-e10f5b0b7eea/Solution.cpp:22:34: error: conversion from ‘time_point<[...],duration<[...],ratio<54,[...]>>>’ to non-scalar type ‘time_point<[...],duration<[...],ratio<86400,[...]>>>’ requested
   22 |     sys_days a_month_ago = today - months{1};
      |                            ~~~~~~^~~~~~~~~~~
 55%|█████▌    | 203/369 [42:47<36:05, 13.04s/it] 55%|█████▌    | 204/369 [42:50<27:31, 10.01s/it] 56%|█████▌    | 205/369 [42:55<22:55,  8.39s/it] 56%|█████▌    | 206/369 [42:59<19:20,  7.12s/it] 56%|█████▌    | 207/369 [43:19<29:28, 10.92s/it] 56%|█████▋    | 208/369 [43:25<25:19,  9.44s/it] 57%|█████▋    | 209/369 [43:44<33:08, 12.43s/it] 57%|█████▋    | 210/369 [43:49<26:43, 10.09s/it] 57%|█████▋    | 211/369 [43:51<20:39,  7.84s/it] 57%|█████▋    | 212/369 [43:54<16:29,  6.31s/it]llm_build/f53ede06-2877-11f0-8add-e10f5b0b7eea/Solution.cpp: In function ‘int main()’:
llm_build/f53ede06-2877-11f0-8add-e10f5b0b7eea/Solution.cpp:18:35: error: conversion from ‘time_point<[...],duration<[...],ratio<216,[...]>>>’ to non-scalar type ‘time_point<[...],duration<[...],ratio<86400,[...]>>>’ requested
   18 |     sys_days one_year_ago = today - years{1};
      |                             ~~~~~~^~~~~~~~~~
 58%|█████▊    | 213/369 [43:57<13:31,  5.20s/it] 58%|█████▊    | 214/369 [44:00<12:16,  4.75s/it] 58%|█████▊    | 215/369 [44:03<10:11,  3.97s/it] 59%|█████▊    | 216/369 [44:17<18:07,  7.11s/it] 59%|█████▉    | 217/369 [44:19<14:09,  5.59s/it] 59%|█████▉    | 218/369 [44:26<14:41,  5.84s/it] 59%|█████▉    | 219/369 [44:45<25:03, 10.02s/it] 60%|█████▉    | 220/369 [44:49<19:52,  8.00s/it] 60%|█████▉    | 221/369 [44:53<16:57,  6.88s/it]llm_build/183edce4-2878-11f0-8add-e10f5b0b7eea/Solution.cpp: In function ‘int main()’:
llm_build/183edce4-2878-11f0-8add-e10f5b0b7eea/Solution.cpp:22:35: error: conversion from ‘time_point<[...],duration<[...],ratio<216,[...]>>>’ to non-scalar type ‘time_point<[...],duration<[...],ratio<86400,[...]>>>’ requested
   22 |     sys_days one_year_ago = today - years{1};
      |                             ~~~~~~^~~~~~~~~~
 60%|██████    | 222/369 [44:56<13:52,  5.67s/it] 60%|██████    | 223/369 [44:59<12:19,  5.07s/it] 61%|██████    | 224/369 [45:02<10:22,  4.30s/it] 61%|██████    | 225/369 [45:06<10:24,  4.34s/it] 61%|██████    | 226/369 [45:18<15:43,  6.60s/it] 62%|██████▏   | 227/369 [45:21<12:43,  5.38s/it] 62%|██████▏   | 228/369 [45:26<12:43,  5.41s/it] 62%|██████▏   | 229/369 [45:46<22:25,  9.61s/it] 62%|██████▏   | 230/369 [45:49<17:46,  7.67s/it] 63%|██████▎   | 231/369 [45:51<14:02,  6.10s/it] 63%|██████▎   | 232/369 [45:54<11:49,  5.18s/it] 63%|██████▎   | 233/369 [45:58<10:54,  4.81s/it] 63%|██████▎   | 234/369 [46:01<09:18,  4.13s/it] 64%|██████▎   | 235/369 [46:03<08:01,  3.59s/it] 64%|██████▍   | 236/369 [46:49<36:05, 16.28s/it] 64%|██████▍   | 237/369 [46:51<26:40, 12.12s/it] 64%|██████▍   | 238/369 [46:55<20:35,  9.43s/it] 65%|██████▍   | 239/369 [46:57<16:01,  7.39s/it] 65%|██████▌   | 240/369 [47:01<13:16,  6.18s/it] 65%|██████▌   | 241/369 [47:04<11:08,  5.22s/it] 66%|██████▌   | 242/369 [47:08<10:27,  4.94s/it] 66%|██████▌   | 243/369 [47:51<34:25, 16.40s/it] 66%|██████▌   | 244/369 [47:54<26:07, 12.54s/it] 66%|██████▋   | 245/369 [47:58<20:15,  9.80s/it] 67%|██████▋   | 246/369 [48:00<15:39,  7.64s/it] 67%|██████▋   | 247/369 [48:03<12:35,  6.19s/it] 67%|██████▋   | 248/369 [48:06<10:20,  5.13s/it]llm_build/91d09516-2878-11f0-8ade-e10f5b0b7eea/Solution.cpp: In function ‘int main()’:
llm_build/91d09516-2878-11f0-8ade-e10f5b0b7eea/Solution.cpp:23:35: error: conversion from ‘time_point<[...],duration<[...],ratio<216,[...]>>>’ to non-scalar type ‘time_point<[...],duration<[...],ratio<86400,[...]>>>’ requested
   23 |     sys_days one_year_ago = today - years{1};
      |                             ~~~~~~^~~~~~~~~~
 67%|██████▋   | 249/369 [48:19<15:18,  7.65s/it] 68%|██████▊   | 250/369 [48:22<11:59,  6.04s/it] 68%|██████▊   | 251/369 [48:35<15:57,  8.11s/it] 68%|██████▊   | 252/369 [48:46<17:49,  9.14s/it] 69%|██████▊   | 253/369 [48:49<14:00,  7.25s/it] 69%|██████▉   | 254/369 [48:52<11:19,  5.91s/it] 69%|██████▉   | 255/369 [48:54<09:19,  4.90s/it] 69%|██████▉   | 256/369 [48:57<07:57,  4.23s/it] 70%|██████▉   | 257/369 [48:59<06:51,  3.68s/it] 70%|██████▉   | 258/369 [49:02<06:12,  3.36s/it] 70%|███████   | 259/369 [49:05<05:41,  3.10s/it] 70%|███████   | 260/369 [49:08<05:46,  3.18s/it] 71%|███████   | 261/369 [49:19<10:12,  5.67s/it] 71%|███████   | 262/369 [49:23<09:10,  5.15s/it] 71%|███████▏  | 263/369 [49:30<10:02,  5.68s/it] 72%|███████▏  | 264/369 [49:33<08:23,  4.80s/it] 72%|███████▏  | 265/369 [49:46<12:48,  7.39s/it] 72%|███████▏  | 266/369 [49:53<12:07,  7.06s/it]llm_build/cad0c246-2878-11f0-8adf-e10f5b0b7eea/Solution.cpp: In function ‘int main()’:
llm_build/cad0c246-2878-11f0-8adf-e10f5b0b7eea/Solution.cpp:22:35: error: conversion from ‘time_point<[...],duration<[...],ratio<216,[...]>>>’ to non-scalar type ‘time_point<[...],duration<[...],ratio<86400,[...]>>>’ requested
   22 |     sys_days one_year_ago = today - years{1};
      |                             ~~~~~~^~~~~~~~~~
 72%|███████▏  | 267/369 [49:55<09:35,  5.65s/it] 73%|███████▎  | 268/369 [49:58<08:17,  4.92s/it] 73%|███████▎  | 269/369 [50:02<07:30,  4.51s/it] 73%|███████▎  | 270/369 [50:05<06:52,  4.16s/it] 73%|███████▎  | 271/369 [50:08<05:54,  3.62s/it] 74%|███████▎  | 272/369 [50:20<10:12,  6.31s/it] 74%|███████▍  | 273/369 [50:23<08:17,  5.18s/it] 74%|███████▍  | 274/369 [50:25<06:54,  4.36s/it] 75%|███████▍  | 275/369 [50:33<08:21,  5.34s/it]llm_build/e9e9828a-2878-11f0-8adf-e10f5b0b7eea/Solution.cpp: In function ‘int main()’:
llm_build/e9e9828a-2878-11f0-8adf-e10f5b0b7eea/Solution.cpp:18:35: error: conversion from ‘time_point<[...],duration<[...],ratio<216,[...]>>>’ to non-scalar type ‘time_point<[...],duration<[...],ratio<86400,[...]>>>’ requested
   18 |     sys_days one_year_ago = today - years{1};
      |                             ~~~~~~^~~~~~~~~~
 75%|███████▍  | 276/369 [50:47<12:31,  8.08s/it] 75%|███████▌  | 277/369 [50:50<09:47,  6.39s/it] 75%|███████▌  | 278/369 [50:55<09:00,  5.94s/it] 76%|███████▌  | 279/369 [50:58<07:49,  5.22s/it] 76%|███████▌  | 280/369 [51:01<06:42,  4.52s/it] 76%|███████▌  | 281/369 [51:04<06:08,  4.18s/it] 76%|███████▋  | 282/369 [51:07<05:21,  3.70s/it] 77%|███████▋  | 283/369 [51:10<05:02,  3.52s/it] 77%|███████▋  | 284/369 [51:21<08:16,  5.84s/it] 77%|███████▋  | 285/369 [51:33<10:43,  7.66s/it] 78%|███████▊  | 286/369 [51:49<13:47,  9.97s/it] 78%|███████▊  | 287/369 [51:58<13:28,  9.86s/it] 78%|███████▊  | 288/369 [52:00<10:13,  7.58s/it] 78%|███████▊  | 289/369 [52:03<08:04,  6.06s/it] 79%|███████▊  | 290/369 [52:06<06:34,  5.00s/it] 79%|███████▉  | 291/369 [52:09<05:48,  4.47s/it] 79%|███████▉  | 292/369 [52:12<05:08,  4.00s/it]llm_build/21d63c6a-2879-11f0-8ae0-e10f5b0b7eea/Solution.cpp: In function ‘int main()’:
llm_build/21d63c6a-2879-11f0-8ae0-e10f5b0b7eea/Solution.cpp:22:34: error: conversion from ‘time_point<[...],duration<[...],ratio<54,[...]>>>’ to non-scalar type ‘time_point<[...],duration<[...],ratio<86400,[...]>>>’ requested
   22 |     sys_days a_month_ago = today - months{1};
      |                            ~~~~~~^~~~~~~~~~~
Traceback (most recent call last):
  File "/home/doyle/Documents/COS484/COS484_PAL/.venv/lib/python3.10/site-packages/pal/core/interface.py", line 185, in run
    exec_result = self.execute(code)
  File "/home/doyle/Documents/COS484/COS484_PAL/.venv/lib/python3.10/site-packages/pal/core/interface.py", line 114, in execute
    self.runtime.exec_code('\n'.join(code))
  File "/home/doyle/Documents/COS484/COS484_PAL/.venv/lib/python3.10/site-packages/pal/core/runtime.py", line 206, in exec_code
    result = subprocess.run([f"llm_build/{str(random_uuid)}/Solution"], capture_output=True)
  File "/usr/lib/python3.10/subprocess.py", line 503, in run
    with Popen(*popenargs, **kwargs) as process:
  File "/usr/lib/python3.10/subprocess.py", line 971, in __init__
    self._execute_child(args, executable, preexec_fn, close_fds,
  File "/usr/lib/python3.10/subprocess.py", line 1863, in _execute_child
    raise child_exception_type(errno_num, err_msg, err_filename)
FileNotFoundError: [Errno 2] No such file or directory: 'llm_build/b9ca7204-2877-11f0-8add-e10f5b0b7eea/Solution'

Execute error: 
Traceback (most recent call last):
  File "/home/doyle/Documents/COS484/COS484_PAL/.venv/lib/python3.10/site-packages/pal/core/interface.py", line 185, in run
    exec_result = self.execute(code)
  File "/home/doyle/Documents/COS484/COS484_PAL/.venv/lib/python3.10/site-packages/pal/core/interface.py", line 114, in execute
    self.runtime.exec_code('\n'.join(code))
  File "/home/doyle/Documents/COS484/COS484_PAL/.venv/lib/python3.10/site-packages/pal/core/runtime.py", line 206, in exec_code
    result = subprocess.run([f"llm_build/{str(random_uuid)}/Solution"], capture_output=True)
  File "/usr/lib/python3.10/subprocess.py", line 503, in run
    with Popen(*popenargs, **kwargs) as process:
  File "/usr/lib/python3.10/subprocess.py", line 971, in __init__
    self._execute_child(args, executable, preexec_fn, close_fds,
  File "/usr/lib/python3.10/subprocess.py", line 1863, in _execute_child
    raise child_exception_type(errno_num, err_msg, err_filename)
FileNotFoundError: [Errno 2] No such file or directory: 'llm_build/cbd1b0d4-2877-11f0-8add-e10f5b0b7eea/Solution'

Execute error: 
Traceback (most recent call last):
  File "/home/doyle/Documents/COS484/COS484_PAL/.venv/lib/python3.10/site-packages/pal/core/interface.py", line 185, in run
    exec_result = self.execute(code)
  File "/home/doyle/Documents/COS484/COS484_PAL/.venv/lib/python3.10/site-packages/pal/core/interface.py", line 114, in execute
    self.runtime.exec_code('\n'.join(code))
  File "/home/doyle/Documents/COS484/COS484_PAL/.venv/lib/python3.10/site-packages/pal/core/runtime.py", line 206, in exec_code
    result = subprocess.run([f"llm_build/{str(random_uuid)}/Solution"], capture_output=True)
  File "/usr/lib/python3.10/subprocess.py", line 503, in run
    with Popen(*popenargs, **kwargs) as process:
  File "/usr/lib/python3.10/subprocess.py", line 971, in __init__
    self._execute_child(args, executable, preexec_fn, close_fds,
  File "/usr/lib/python3.10/subprocess.py", line 1863, in _execute_child
    raise child_exception_type(errno_num, err_msg, err_filename)
FileNotFoundError: [Errno 2] No such file or directory: 'llm_build/f53ede06-2877-11f0-8add-e10f5b0b7eea/Solution'

Execute error: 
Traceback (most recent call last):
  File "/home/doyle/Documents/COS484/COS484_PAL/.venv/lib/python3.10/site-packages/pal/core/interface.py", line 185, in run
    exec_result = self.execute(code)
  File "/home/doyle/Documents/COS484/COS484_PAL/.venv/lib/python3.10/site-packages/pal/core/interface.py", line 114, in execute
    self.runtime.exec_code('\n'.join(code))
  File "/home/doyle/Documents/COS484/COS484_PAL/.venv/lib/python3.10/site-packages/pal/core/runtime.py", line 206, in exec_code
    result = subprocess.run([f"llm_build/{str(random_uuid)}/Solution"], capture_output=True)
  File "/usr/lib/python3.10/subprocess.py", line 503, in run
    with Popen(*popenargs, **kwargs) as process:
  File "/usr/lib/python3.10/subprocess.py", line 971, in __init__
    self._execute_child(args, executable, preexec_fn, close_fds,
  File "/usr/lib/python3.10/subprocess.py", line 1863, in _execute_child
    raise child_exception_type(errno_num, err_msg, err_filename)
FileNotFoundError: [Errno 2] No such file or directory: 'llm_build/183edce4-2878-11f0-8add-e10f5b0b7eea/Solution'

Execute error: 
Traceback (most recent call last):
  File "/home/doyle/Documents/COS484/COS484_PAL/.venv/lib/python3.10/site-packages/pal/core/interface.py", line 185, in run
    exec_result = self.execute(code)
  File "/home/doyle/Documents/COS484/COS484_PAL/.venv/lib/python3.10/site-packages/pal/core/interface.py", line 114, in execute
    self.runtime.exec_code('\n'.join(code))
  File "/home/doyle/Documents/COS484/COS484_PAL/.venv/lib/python3.10/site-packages/pal/core/runtime.py", line 206, in exec_code
    result = subprocess.run([f"llm_build/{str(random_uuid)}/Solution"], capture_output=True)
  File "/usr/lib/python3.10/subprocess.py", line 503, in run
    with Popen(*popenargs, **kwargs) as process:
  File "/usr/lib/python3.10/subprocess.py", line 971, in __init__
    self._execute_child(args, executable, preexec_fn, close_fds,
  File "/usr/lib/python3.10/subprocess.py", line 1863, in _execute_child
    raise child_exception_type(errno_num, err_msg, err_filename)
FileNotFoundError: [Errno 2] No such file or directory: 'llm_build/91d09516-2878-11f0-8ade-e10f5b0b7eea/Solution'

Execute error: 
Traceback (most recent call last):
  File "/home/doyle/Documents/COS484/COS484_PAL/.venv/lib/python3.10/site-packages/pal/core/interface.py", line 185, in run
    exec_result = self.execute(code)
  File "/home/doyle/Documents/COS484/COS484_PAL/.venv/lib/python3.10/site-packages/pal/core/interface.py", line 114, in execute
    self.runtime.exec_code('\n'.join(code))
  File "/home/doyle/Documents/COS484/COS484_PAL/.venv/lib/python3.10/site-packages/pal/core/runtime.py", line 206, in exec_code
    result = subprocess.run([f"llm_build/{str(random_uuid)}/Solution"], capture_output=True)
  File "/usr/lib/python3.10/subprocess.py", line 503, in run
    with Popen(*popenargs, **kwargs) as process:
  File "/usr/lib/python3.10/subprocess.py", line 971, in __init__
    self._execute_child(args, executable, preexec_fn, close_fds,
  File "/usr/lib/python3.10/subprocess.py", line 1863, in _execute_child
    raise child_exception_type(errno_num, err_msg, err_filename)
FileNotFoundError: [Errno 2] No such file or directory: 'llm_build/cad0c246-2878-11f0-8adf-e10f5b0b7eea/Solution'

Execute error: 
Traceback (most recent call last):
  File "/home/doyle/Documents/COS484/COS484_PAL/.venv/lib/python3.10/site-packages/pal/core/interface.py", line 185, in run
    exec_result = self.execute(code)
  File "/home/doyle/Documents/COS484/COS484_PAL/.venv/lib/python3.10/site-packages/pal/core/interface.py", line 114, in execute
    self.runtime.exec_code('\n'.join(code))
  File "/home/doyle/Documents/COS484/COS484_PAL/.venv/lib/python3.10/site-packages/pal/core/runtime.py", line 206, in exec_code
    result = subprocess.run([f"llm_build/{str(random_uuid)}/Solution"], capture_output=True)
  File "/usr/lib/python3.10/subprocess.py", line 503, in run
    with Popen(*popenargs, **kwargs) as process:
  File "/usr/lib/python3.10/subprocess.py", line 971, in __init__
    self._execute_child(args, executable, preexec_fn, close_fds,
  File "/usr/lib/python3.10/subprocess.py", line 1863, in _execute_child
    raise child_exception_type(errno_num, err_msg, err_filename)
FileNotFoundError: [Errno 2] No such file or directory: 'llm_build/e9e9828a-2878-11f0-8adf-e10f5b0b7eea/Solution'

Execute error: 
 79%|███████▉  | 293/369 [52:21<07:10,  5.66s/it] 80%|███████▉  | 294/369 [52:27<07:06,  5.68s/it] 80%|███████▉  | 295/369 [52:58<16:26, 13.34s/it] 80%|████████  | 296/369 [53:01<12:21, 10.16s/it] 80%|████████  | 297/369 [53:04<09:29,  7.91s/it] 81%|████████  | 298/369 [53:06<07:27,  6.31s/it] 81%|████████  | 299/369 [53:11<06:52,  5.89s/it] 81%|████████▏ | 300/369 [53:22<08:30,  7.40s/it] 82%|████████▏ | 301/369 [53:27<07:28,  6.60s/it]llm_build/4acb7e1e-2879-11f0-8ae0-e10f5b0b7eea/Solution.cpp: In function ‘int main()’:
llm_build/4acb7e1e-2879-11f0-8ae0-e10f5b0b7eea/Solution.cpp:18:34: error: conversion from ‘time_point<[...],duration<[...],ratio<54,[...]>>>’ to non-scalar type ‘time_point<[...],duration<[...],ratio<86400,[...]>>>’ requested
   18 |     sys_days a_month_ago = today - months{1};
      |                            ~~~~~~^~~~~~~~~~~
 82%|████████▏ | 302/369 [53:30<06:13,  5.58s/it]llm_build/4cb17512-2879-11f0-8ae0-e10f5b0b7eea/Solution.cpp: In function ‘int main()’:
llm_build/4cb17512-2879-11f0-8ae0-e10f5b0b7eea/Solution.cpp:18:35: error: conversion from ‘time_point<[...],duration<[...],ratio<216,[...]>>>’ to non-scalar type ‘time_point<[...],duration<[...],ratio<86400,[...]>>>’ requested
   18 |     sys_days one_year_ago = today - years{1};
      |                             ~~~~~~^~~~~~~~~~
 82%|████████▏ | 303/369 [53:33<05:15,  4.79s/it] 82%|████████▏ | 304/369 [53:49<08:46,  8.10s/it] 83%|████████▎ | 305/369 [53:52<07:06,  6.66s/it] 83%|████████▎ | 306/369 [53:59<07:10,  6.83s/it] 83%|████████▎ | 307/369 [54:02<05:46,  5.59s/it] 83%|████████▎ | 308/369 [54:05<04:59,  4.91s/it] 84%|████████▎ | 309/369 [54:12<05:31,  5.52s/it] 84%|████████▍ | 310/369 [54:15<04:39,  4.73s/it] 84%|████████▍ | 311/369 [54:22<05:16,  5.45s/it]llm_build/70ff19e2-2879-11f0-8ae0-e10f5b0b7eea/Solution.cpp: In function ‘int main()’:
llm_build/70ff19e2-2879-11f0-8ae0-e10f5b0b7eea/Solution.cpp:22:35: error: conversion from ‘time_point<[...],duration<[...],ratio<216,[...]>>>’ to non-scalar type ‘time_point<[...],duration<[...],ratio<86400,[...]>>>’ requested
   22 |     sys_days one_year_ago = today - years{1};
      |                             ~~~~~~^~~~~~~~~~
 85%|████████▍ | 312/369 [54:34<06:57,  7.32s/it] 85%|████████▍ | 313/369 [54:48<08:52,  9.51s/it] 85%|████████▌ | 314/369 [55:01<09:34, 10.44s/it] 85%|████████▌ | 315/369 [55:05<07:35,  8.43s/it] 86%|████████▌ | 316/369 [55:08<06:03,  6.85s/it] 86%|████████▌ | 317/369 [55:11<04:51,  5.61s/it] 86%|████████▌ | 318/369 [55:14<04:05,  4.82s/it] 86%|████████▋ | 319/369 [55:20<04:25,  5.30s/it] 87%|████████▋ | 320/369 [55:23<03:47,  4.65s/it]llm_build/905e0ffa-2879-11f0-8ae0-e10f5b0b7eea/Solution.cpp: In function ‘int main()’:
llm_build/905e0ffa-2879-11f0-8ae0-e10f5b0b7eea/Solution.cpp:22:35: error: conversion from ‘time_point<[...],duration<[...],ratio<216,[...]>>>’ to non-scalar type ‘time_point<[...],duration<[...],ratio<86400,[...]>>>’ requested
   22 |     sys_days one_year_ago = today - years{1};
      |                             ~~~~~~^~~~~~~~~~
 87%|████████▋ | 321/369 [55:27<03:24,  4.26s/it] 87%|████████▋ | 322/369 [55:35<04:22,  5.58s/it] 88%|████████▊ | 323/369 [55:50<06:20,  8.26s/it] 88%|████████▊ | 324/369 [56:02<06:59,  9.32s/it] 88%|████████▊ | 325/369 [56:06<05:43,  7.80s/it] 88%|████████▊ | 326/369 [56:08<04:26,  6.19s/it] 89%|████████▊ | 327/369 [56:11<03:41,  5.28s/it] 89%|████████▉ | 328/369 [56:14<03:01,  4.43s/it]llm_build/ae559bc2-2879-11f0-8ae0-e10f5b0b7eea/Solution.cpp: In function ‘int main()’:
llm_build/ae559bc2-2879-11f0-8ae0-e10f5b0b7eea/Solution.cpp:22:39: error: conversion from ‘time_point<[...],duration<[...],ratio<54,[...]>>>’ to non-scalar type ‘time_point<[...],duration<[...],ratio<86400,[...]>>>’ requested
   22 |     sys_days a_month_ago = today_days - months{1};
      |                            ~~~~~~~~~~~^~~~~~~~~~~
 89%|████████▉ | 329/369 [56:17<02:40,  4.01s/it] 89%|████████▉ | 330/369 [56:23<03:01,  4.64s/it] 90%|████████▉ | 331/369 [56:27<02:48,  4.44s/it] 90%|████████▉ | 332/369 [56:30<02:26,  3.96s/it] 90%|█████████ | 333/369 [56:32<02:04,  3.45s/it]llm_build/b8c08a86-2879-11f0-8ae0-e10f5b0b7eea/Solution.cpp: In function ‘int main()’:
llm_build/b8c08a86-2879-11f0-8ae0-e10f5b0b7eea/Solution.cpp:20:35: error: conversion from ‘time_point<[...],duration<[...],ratio<216,[...]>>>’ to non-scalar type ‘time_point<[...],duration<[...],ratio<86400,[...]>>>’ requested
   20 |     sys_days today = wedding_date + years{5};
      |                      ~~~~~~~~~~~~~^~~~~~~~~~
 91%|█████████ | 334/369 [56:34<01:47,  3.08s/it]llm_build/c9c7e3a6-2879-11f0-8ae1-e10f5b0b7eea/Solution.cpp: In function ‘int main()’:
llm_build/c9c7e3a6-2879-11f0-8ae1-e10f5b0b7eea/Solution.cpp:20:35: error: conversion from ‘time_point<[...],duration<[...],ratio<216,[...]>>>’ to non-scalar type ‘time_point<[...],duration<[...],ratio<86400,[...]>>>’ requested
   20 |     sys_days today = wedding_date + years{5};
      |                      ~~~~~~~~~~~~~^~~~~~~~~~
Traceback (most recent call last):
  File "/home/doyle/Documents/COS484/COS484_PAL/.venv/lib/python3.10/site-packages/pal/core/interface.py", line 185, in run
    exec_result = self.execute(code)
  File "/home/doyle/Documents/COS484/COS484_PAL/.venv/lib/python3.10/site-packages/pal/core/interface.py", line 114, in execute
    self.runtime.exec_code('\n'.join(code))
  File "/home/doyle/Documents/COS484/COS484_PAL/.venv/lib/python3.10/site-packages/pal/core/runtime.py", line 206, in exec_code
    result = subprocess.run([f"llm_build/{str(random_uuid)}/Solution"], capture_output=True)
  File "/usr/lib/python3.10/subprocess.py", line 503, in run
    with Popen(*popenargs, **kwargs) as process:
  File "/usr/lib/python3.10/subprocess.py", line 971, in __init__
    self._execute_child(args, executable, preexec_fn, close_fds,
  File "/usr/lib/python3.10/subprocess.py", line 1863, in _execute_child
    raise child_exception_type(errno_num, err_msg, err_filename)
FileNotFoundError: [Errno 2] No such file or directory: 'llm_build/21d63c6a-2879-11f0-8ae0-e10f5b0b7eea/Solution'

Execute error: 
Traceback (most recent call last):
  File "/home/doyle/Documents/COS484/COS484_PAL/.venv/lib/python3.10/site-packages/pal/core/interface.py", line 185, in run
    exec_result = self.execute(code)
  File "/home/doyle/Documents/COS484/COS484_PAL/.venv/lib/python3.10/site-packages/pal/core/interface.py", line 114, in execute
    self.runtime.exec_code('\n'.join(code))
  File "/home/doyle/Documents/COS484/COS484_PAL/.venv/lib/python3.10/site-packages/pal/core/runtime.py", line 206, in exec_code
    result = subprocess.run([f"llm_build/{str(random_uuid)}/Solution"], capture_output=True)
  File "/usr/lib/python3.10/subprocess.py", line 503, in run
    with Popen(*popenargs, **kwargs) as process:
  File "/usr/lib/python3.10/subprocess.py", line 971, in __init__
    self._execute_child(args, executable, preexec_fn, close_fds,
  File "/usr/lib/python3.10/subprocess.py", line 1863, in _execute_child
    raise child_exception_type(errno_num, err_msg, err_filename)
FileNotFoundError: [Errno 2] No such file or directory: 'llm_build/4acb7e1e-2879-11f0-8ae0-e10f5b0b7eea/Solution'

Execute error: 
Traceback (most recent call last):
  File "/home/doyle/Documents/COS484/COS484_PAL/.venv/lib/python3.10/site-packages/pal/core/interface.py", line 185, in run
    exec_result = self.execute(code)
  File "/home/doyle/Documents/COS484/COS484_PAL/.venv/lib/python3.10/site-packages/pal/core/interface.py", line 114, in execute
    self.runtime.exec_code('\n'.join(code))
  File "/home/doyle/Documents/COS484/COS484_PAL/.venv/lib/python3.10/site-packages/pal/core/runtime.py", line 206, in exec_code
    result = subprocess.run([f"llm_build/{str(random_uuid)}/Solution"], capture_output=True)
  File "/usr/lib/python3.10/subprocess.py", line 503, in run
    with Popen(*popenargs, **kwargs) as process:
  File "/usr/lib/python3.10/subprocess.py", line 971, in __init__
    self._execute_child(args, executable, preexec_fn, close_fds,
  File "/usr/lib/python3.10/subprocess.py", line 1863, in _execute_child
    raise child_exception_type(errno_num, err_msg, err_filename)
FileNotFoundError: [Errno 2] No such file or directory: 'llm_build/4cb17512-2879-11f0-8ae0-e10f5b0b7eea/Solution'

Execute error: 
Traceback (most recent call last):
  File "/home/doyle/Documents/COS484/COS484_PAL/.venv/lib/python3.10/site-packages/pal/core/interface.py", line 185, in run
    exec_result = self.execute(code)
  File "/home/doyle/Documents/COS484/COS484_PAL/.venv/lib/python3.10/site-packages/pal/core/interface.py", line 114, in execute
    self.runtime.exec_code('\n'.join(code))
  File "/home/doyle/Documents/COS484/COS484_PAL/.venv/lib/python3.10/site-packages/pal/core/runtime.py", line 206, in exec_code
    result = subprocess.run([f"llm_build/{str(random_uuid)}/Solution"], capture_output=True)
  File "/usr/lib/python3.10/subprocess.py", line 503, in run
    with Popen(*popenargs, **kwargs) as process:
  File "/usr/lib/python3.10/subprocess.py", line 971, in __init__
    self._execute_child(args, executable, preexec_fn, close_fds,
  File "/usr/lib/python3.10/subprocess.py", line 1863, in _execute_child
    raise child_exception_type(errno_num, err_msg, err_filename)
FileNotFoundError: [Errno 2] No such file or directory: 'llm_build/70ff19e2-2879-11f0-8ae0-e10f5b0b7eea/Solution'

Execute error: 
Traceback (most recent call last):
  File "/home/doyle/Documents/COS484/COS484_PAL/.venv/lib/python3.10/site-packages/pal/core/interface.py", line 185, in run
    exec_result = self.execute(code)
  File "/home/doyle/Documents/COS484/COS484_PAL/.venv/lib/python3.10/site-packages/pal/core/interface.py", line 114, in execute
    self.runtime.exec_code('\n'.join(code))
  File "/home/doyle/Documents/COS484/COS484_PAL/.venv/lib/python3.10/site-packages/pal/core/runtime.py", line 206, in exec_code
    result = subprocess.run([f"llm_build/{str(random_uuid)}/Solution"], capture_output=True)
  File "/usr/lib/python3.10/subprocess.py", line 503, in run
    with Popen(*popenargs, **kwargs) as process:
  File "/usr/lib/python3.10/subprocess.py", line 971, in __init__
    self._execute_child(args, executable, preexec_fn, close_fds,
  File "/usr/lib/python3.10/subprocess.py", line 1863, in _execute_child
    raise child_exception_type(errno_num, err_msg, err_filename)
FileNotFoundError: [Errno 2] No such file or directory: 'llm_build/905e0ffa-2879-11f0-8ae0-e10f5b0b7eea/Solution'

Execute error: 
Traceback (most recent call last):
  File "/home/doyle/Documents/COS484/COS484_PAL/.venv/lib/python3.10/site-packages/pal/core/interface.py", line 185, in run
    exec_result = self.execute(code)
  File "/home/doyle/Documents/COS484/COS484_PAL/.venv/lib/python3.10/site-packages/pal/core/interface.py", line 114, in execute
    self.runtime.exec_code('\n'.join(code))
  File "/home/doyle/Documents/COS484/COS484_PAL/.venv/lib/python3.10/site-packages/pal/core/runtime.py", line 206, in exec_code
    result = subprocess.run([f"llm_build/{str(random_uuid)}/Solution"], capture_output=True)
  File "/usr/lib/python3.10/subprocess.py", line 503, in run
    with Popen(*popenargs, **kwargs) as process:
  File "/usr/lib/python3.10/subprocess.py", line 971, in __init__
    self._execute_child(args, executable, preexec_fn, close_fds,
  File "/usr/lib/python3.10/subprocess.py", line 1863, in _execute_child
    raise child_exception_type(errno_num, err_msg, err_filename)
FileNotFoundError: [Errno 2] No such file or directory: 'llm_build/ae559bc2-2879-11f0-8ae0-e10f5b0b7eea/Solution'

Execute error: 
Traceback (most recent call last):
  File "/home/doyle/Documents/COS484/COS484_PAL/.venv/lib/python3.10/site-packages/pal/core/interface.py", line 185, in run
    exec_result = self.execute(code)
  File "/home/doyle/Documents/COS484/COS484_PAL/.venv/lib/python3.10/site-packages/pal/core/interface.py", line 114, in execute
    self.runtime.exec_code('\n'.join(code))
  File "/home/doyle/Documents/COS484/COS484_PAL/.venv/lib/python3.10/site-packages/pal/core/runtime.py", line 206, in exec_code
    result = subprocess.run([f"llm_build/{str(random_uuid)}/Solution"], capture_output=True)
  File "/usr/lib/python3.10/subprocess.py", line 503, in run
    with Popen(*popenargs, **kwargs) as process:
  File "/usr/lib/python3.10/subprocess.py", line 971, in __init__
    self._execute_child(args, executable, preexec_fn, close_fds,
  File "/usr/lib/python3.10/subprocess.py", line 1863, in _execute_child
    raise child_exception_type(errno_num, err_msg, err_filename)
FileNotFoundError: [Errno 2] No such file or directory: 'llm_build/b8c08a86-2879-11f0-8ae0-e10f5b0b7eea/Solution'

Execute error: 
 91%|█████████ | 335/369 [57:03<06:05, 10.75s/it] 91%|█████████ | 336/369 [57:08<04:56,  8.99s/it]llm_build/ce246e56-2879-11f0-8ae1-e10f5b0b7eea/Solution.cpp: In function ‘int main()’:
llm_build/ce246e56-2879-11f0-8ae1-e10f5b0b7eea/Solution.cpp:20:35: error: conversion from ‘time_point<[...],duration<[...],ratio<216,[...]>>>’ to non-scalar type ‘time_point<[...],duration<[...],ratio<86400,[...]>>>’ requested
   20 |     sys_days today = wedding_date + years{5};
      |                      ~~~~~~~~~~~~~^~~~~~~~~~
 91%|█████████▏| 337/369 [57:10<03:45,  7.04s/it]llm_build/cf8f7b46-2879-11f0-8ae1-e10f5b0b7eea/Solution.cpp: In function ‘int main()’:
llm_build/cf8f7b46-2879-11f0-8ae1-e10f5b0b7eea/Solution.cpp:19:39: error: conversion from ‘time_point<[...],duration<[...],ratio<54,[...]>>>’ to non-scalar type ‘time_point<[...],duration<[...],ratio<86400,[...]>>>’ requested
   19 |     sys_days a_month_ago = today_days - months{1};
      |                            ~~~~~~~~~~~^~~~~~~~~~~
 92%|█████████▏| 338/369 [57:13<02:54,  5.61s/it]llm_build/d1a717a4-2879-11f0-8ae1-e10f5b0b7eea/Solution.cpp: In function ‘int main()’:
llm_build/d1a717a4-2879-11f0-8ae1-e10f5b0b7eea/Solution.cpp:20:35: error: conversion from ‘time_point<[...],duration<[...],ratio<216,[...]>>>’ to non-scalar type ‘time_point<[...],duration<[...],ratio<86400,[...]>>>’ requested
   20 |     sys_days today = wedding_date + years{5};
      |                      ~~~~~~~~~~~~~^~~~~~~~~~
llm_build/d1a717a4-2879-11f0-8ae1-e10f5b0b7eea/Solution.cpp:23:35: error: conversion from ‘time_point<[...],duration<[...],ratio<216,[...]>>>’ to non-scalar type ‘time_point<[...],duration<[...],ratio<86400,[...]>>>’ requested
   23 |     sys_days one_year_ago = today - years{1};
      |                             ~~~~~~^~~~~~~~~~
 92%|█████████▏| 339/369 [57:16<02:29,  4.98s/it]llm_build/d347c7c0-2879-11f0-8ae1-e10f5b0b7eea/Solution.cpp: In function ‘int main()’:
llm_build/d347c7c0-2879-11f0-8ae1-e10f5b0b7eea/Solution.cpp:20:35: error: conversion from ‘time_point<[...],duration<[...],ratio<216,[...]>>>’ to non-scalar type ‘time_point<[...],duration<[...],ratio<86400,[...]>>>’ requested
   20 |     sys_days today = wedding_date + years{5};
      |                      ~~~~~~~~~~~~~^~~~~~~~~~
 92%|█████████▏| 340/369 [57:19<02:04,  4.28s/it] 92%|█████████▏| 341/369 [57:22<01:53,  4.06s/it]llm_build/d6e4f704-2879-11f0-8ae1-e10f5b0b7eea/Solution.cpp: In function ‘int main()’:
llm_build/d6e4f704-2879-11f0-8ae1-e10f5b0b7eea/Solution.cpp:20:35: error: conversion from ‘time_point<[...],duration<[...],ratio<216,[...]>>>’ to non-scalar type ‘time_point<[...],duration<[...],ratio<86400,[...]>>>’ requested
   20 |     sys_days today = wedding_date + years{5};
      |                      ~~~~~~~~~~~~~^~~~~~~~~~
 93%|█████████▎| 342/369 [57:25<01:37,  3.60s/it] 93%|█████████▎| 343/369 [57:28<01:28,  3.40s/it] 93%|█████████▎| 344/369 [57:35<01:56,  4.65s/it] 93%|█████████▎| 345/369 [58:03<04:40, 11.70s/it] 94%|█████████▍| 346/369 [58:08<03:43,  9.70s/it] 94%|█████████▍| 347/369 [58:13<03:00,  8.22s/it] 94%|█████████▍| 348/369 [58:17<02:22,  6.77s/it] 95%|█████████▍| 349/369 [58:19<01:51,  5.56s/it] 95%|█████████▍| 350/369 [58:22<01:28,  4.64s/it] 95%|█████████▌| 351/369 [58:28<01:29,  4.95s/it] 95%|█████████▌| 352/369 [58:36<01:41,  5.97s/it] 96%|█████████▌| 353/369 [59:06<03:32, 13.25s/it] 96%|█████████▌| 354/369 [59:09<02:33, 10.24s/it] 96%|█████████▌| 355/369 [59:12<01:52,  8.03s/it]llm_build/1865bdb2-287a-11f0-8ae1-e10f5b0b7eea/Solution.cpp: In function ‘int main()’:
llm_build/1865bdb2-287a-11f0-8ae1-e10f5b0b7eea/Solution.cpp:22:34: error: conversion from ‘time_point<[...],duration<[...],ratio<54,[...]>>>’ to non-scalar type ‘time_point<[...],duration<[...],ratio<86400,[...]>>>’ requested
   22 |     sys_days a_month_ago = today - months{1};
      |                            ~~~~~~^~~~~~~~~~~
 96%|█████████▋| 356/369 [59:15<01:22,  6.35s/it]llm_build/1a07c6f6-287a-11f0-8ae1-e10f5b0b7eea/Solution.cpp: In function ‘int main()’:
llm_build/1a07c6f6-287a-11f0-8ae1-e10f5b0b7eea/Solution.cpp:22:35: error: conversion from ‘time_point<[...],duration<[...],ratio<216,[...]>>>’ to non-scalar type ‘time_point<[...],duration<[...],ratio<86400,[...]>>>’ requested
   22 |     sys_days one_year_ago = today - years{1};
      |                             ~~~~~~^~~~~~~~~~
Traceback (most recent call last):
  File "/home/doyle/Documents/COS484/COS484_PAL/.venv/lib/python3.10/site-packages/pal/core/interface.py", line 185, in run
    exec_result = self.execute(code)
  File "/home/doyle/Documents/COS484/COS484_PAL/.venv/lib/python3.10/site-packages/pal/core/interface.py", line 114, in execute
    self.runtime.exec_code('\n'.join(code))
  File "/home/doyle/Documents/COS484/COS484_PAL/.venv/lib/python3.10/site-packages/pal/core/runtime.py", line 206, in exec_code
    result = subprocess.run([f"llm_build/{str(random_uuid)}/Solution"], capture_output=True)
  File "/usr/lib/python3.10/subprocess.py", line 503, in run
    with Popen(*popenargs, **kwargs) as process:
  File "/usr/lib/python3.10/subprocess.py", line 971, in __init__
    self._execute_child(args, executable, preexec_fn, close_fds,
  File "/usr/lib/python3.10/subprocess.py", line 1863, in _execute_child
    raise child_exception_type(errno_num, err_msg, err_filename)
FileNotFoundError: [Errno 2] No such file or directory: 'llm_build/c9c7e3a6-2879-11f0-8ae1-e10f5b0b7eea/Solution'

Execute error: 
Traceback (most recent call last):
  File "/home/doyle/Documents/COS484/COS484_PAL/.venv/lib/python3.10/site-packages/pal/core/interface.py", line 185, in run
    exec_result = self.execute(code)
  File "/home/doyle/Documents/COS484/COS484_PAL/.venv/lib/python3.10/site-packages/pal/core/interface.py", line 114, in execute
    self.runtime.exec_code('\n'.join(code))
  File "/home/doyle/Documents/COS484/COS484_PAL/.venv/lib/python3.10/site-packages/pal/core/runtime.py", line 206, in exec_code
    result = subprocess.run([f"llm_build/{str(random_uuid)}/Solution"], capture_output=True)
  File "/usr/lib/python3.10/subprocess.py", line 503, in run
    with Popen(*popenargs, **kwargs) as process:
  File "/usr/lib/python3.10/subprocess.py", line 971, in __init__
    self._execute_child(args, executable, preexec_fn, close_fds,
  File "/usr/lib/python3.10/subprocess.py", line 1863, in _execute_child
    raise child_exception_type(errno_num, err_msg, err_filename)
FileNotFoundError: [Errno 2] No such file or directory: 'llm_build/ce246e56-2879-11f0-8ae1-e10f5b0b7eea/Solution'

Execute error: 
Traceback (most recent call last):
  File "/home/doyle/Documents/COS484/COS484_PAL/.venv/lib/python3.10/site-packages/pal/core/interface.py", line 185, in run
    exec_result = self.execute(code)
  File "/home/doyle/Documents/COS484/COS484_PAL/.venv/lib/python3.10/site-packages/pal/core/interface.py", line 114, in execute
    self.runtime.exec_code('\n'.join(code))
  File "/home/doyle/Documents/COS484/COS484_PAL/.venv/lib/python3.10/site-packages/pal/core/runtime.py", line 206, in exec_code
    result = subprocess.run([f"llm_build/{str(random_uuid)}/Solution"], capture_output=True)
  File "/usr/lib/python3.10/subprocess.py", line 503, in run
    with Popen(*popenargs, **kwargs) as process:
  File "/usr/lib/python3.10/subprocess.py", line 971, in __init__
    self._execute_child(args, executable, preexec_fn, close_fds,
  File "/usr/lib/python3.10/subprocess.py", line 1863, in _execute_child
    raise child_exception_type(errno_num, err_msg, err_filename)
FileNotFoundError: [Errno 2] No such file or directory: 'llm_build/cf8f7b46-2879-11f0-8ae1-e10f5b0b7eea/Solution'

Execute error: 
Traceback (most recent call last):
  File "/home/doyle/Documents/COS484/COS484_PAL/.venv/lib/python3.10/site-packages/pal/core/interface.py", line 185, in run
    exec_result = self.execute(code)
  File "/home/doyle/Documents/COS484/COS484_PAL/.venv/lib/python3.10/site-packages/pal/core/interface.py", line 114, in execute
    self.runtime.exec_code('\n'.join(code))
  File "/home/doyle/Documents/COS484/COS484_PAL/.venv/lib/python3.10/site-packages/pal/core/runtime.py", line 206, in exec_code
    result = subprocess.run([f"llm_build/{str(random_uuid)}/Solution"], capture_output=True)
  File "/usr/lib/python3.10/subprocess.py", line 503, in run
    with Popen(*popenargs, **kwargs) as process:
  File "/usr/lib/python3.10/subprocess.py", line 971, in __init__
    self._execute_child(args, executable, preexec_fn, close_fds,
  File "/usr/lib/python3.10/subprocess.py", line 1863, in _execute_child
    raise child_exception_type(errno_num, err_msg, err_filename)
FileNotFoundError: [Errno 2] No such file or directory: 'llm_build/d1a717a4-2879-11f0-8ae1-e10f5b0b7eea/Solution'

Execute error: 
Traceback (most recent call last):
  File "/home/doyle/Documents/COS484/COS484_PAL/.venv/lib/python3.10/site-packages/pal/core/interface.py", line 185, in run
    exec_result = self.execute(code)
  File "/home/doyle/Documents/COS484/COS484_PAL/.venv/lib/python3.10/site-packages/pal/core/interface.py", line 114, in execute
    self.runtime.exec_code('\n'.join(code))
  File "/home/doyle/Documents/COS484/COS484_PAL/.venv/lib/python3.10/site-packages/pal/core/runtime.py", line 206, in exec_code
    result = subprocess.run([f"llm_build/{str(random_uuid)}/Solution"], capture_output=True)
  File "/usr/lib/python3.10/subprocess.py", line 503, in run
    with Popen(*popenargs, **kwargs) as process:
  File "/usr/lib/python3.10/subprocess.py", line 971, in __init__
    self._execute_child(args, executable, preexec_fn, close_fds,
  File "/usr/lib/python3.10/subprocess.py", line 1863, in _execute_child
    raise child_exception_type(errno_num, err_msg, err_filename)
FileNotFoundError: [Errno 2] No such file or directory: 'llm_build/d347c7c0-2879-11f0-8ae1-e10f5b0b7eea/Solution'

Execute error: 
Traceback (most recent call last):
  File "/home/doyle/Documents/COS484/COS484_PAL/.venv/lib/python3.10/site-packages/pal/core/interface.py", line 185, in run
    exec_result = self.execute(code)
  File "/home/doyle/Documents/COS484/COS484_PAL/.venv/lib/python3.10/site-packages/pal/core/interface.py", line 114, in execute
    self.runtime.exec_code('\n'.join(code))
  File "/home/doyle/Documents/COS484/COS484_PAL/.venv/lib/python3.10/site-packages/pal/core/runtime.py", line 206, in exec_code
    result = subprocess.run([f"llm_build/{str(random_uuid)}/Solution"], capture_output=True)
  File "/usr/lib/python3.10/subprocess.py", line 503, in run
    with Popen(*popenargs, **kwargs) as process:
  File "/usr/lib/python3.10/subprocess.py", line 971, in __init__
    self._execute_child(args, executable, preexec_fn, close_fds,
  File "/usr/lib/python3.10/subprocess.py", line 1863, in _execute_child
    raise child_exception_type(errno_num, err_msg, err_filename)
FileNotFoundError: [Errno 2] No such file or directory: 'llm_build/d6e4f704-2879-11f0-8ae1-e10f5b0b7eea/Solution'

Execute error: 
Traceback (most recent call last):
  File "/home/doyle/Documents/COS484/COS484_PAL/.venv/lib/python3.10/site-packages/pal/core/interface.py", line 185, in run
    exec_result = self.execute(code)
  File "/home/doyle/Documents/COS484/COS484_PAL/.venv/lib/python3.10/site-packages/pal/core/interface.py", line 114, in execute
    self.runtime.exec_code('\n'.join(code))
  File "/home/doyle/Documents/COS484/COS484_PAL/.venv/lib/python3.10/site-packages/pal/core/runtime.py", line 206, in exec_code
    result = subprocess.run([f"llm_build/{str(random_uuid)}/Solution"], capture_output=True)
  File "/usr/lib/python3.10/subprocess.py", line 503, in run
    with Popen(*popenargs, **kwargs) as process:
  File "/usr/lib/python3.10/subprocess.py", line 971, in __init__
    self._execute_child(args, executable, preexec_fn, close_fds,
  File "/usr/lib/python3.10/subprocess.py", line 1863, in _execute_child
    raise child_exception_type(errno_num, err_msg, err_filename)
FileNotFoundError: [Errno 2] No such file or directory: 'llm_build/1865bdb2-287a-11f0-8ae1-e10f5b0b7eea/Solution'

Execute error: 
 97%|█████████▋| 357/369 [59:18<01:03,  5.31s/it] 97%|█████████▋| 358/369 [59:21<00:51,  4.65s/it] 97%|█████████▋| 359/369 [59:23<00:39,  3.96s/it] 98%|█████████▊| 360/369 [59:25<00:31,  3.46s/it] 98%|█████████▊| 361/369 [59:32<00:36,  4.57s/it] 98%|█████████▊| 362/369 [59:35<00:27,  3.94s/it] 98%|█████████▊| 363/369 [1:00:06<01:12, 12.15s/it] 99%|█████████▊| 364/369 [1:00:09<00:46,  9.32s/it] 99%|█████████▉| 365/369 [1:00:13<00:30,  7.63s/it] 99%|█████████▉| 366/369 [1:00:17<00:19,  6.60s/it] 99%|█████████▉| 367/369 [1:00:20<00:11,  5.72s/it]100%|█████████▉| 368/369 [1:00:25<00:05,  5.35s/it]100%|██████████| 369/369 [1:00:29<00:00,  4.94s/it]100%|██████████| 369/369 [1:00:29<00:00,  9.84s/it]
Traceback (most recent call last):
  File "/home/doyle/Documents/COS484/COS484_PAL/.venv/lib/python3.10/site-packages/pal/core/interface.py", line 185, in run
    exec_result = self.execute(code)
  File "/home/doyle/Documents/COS484/COS484_PAL/.venv/lib/python3.10/site-packages/pal/core/interface.py", line 114, in execute
    self.runtime.exec_code('\n'.join(code))
  File "/home/doyle/Documents/COS484/COS484_PAL/.venv/lib/python3.10/site-packages/pal/core/runtime.py", line 206, in exec_code
    result = subprocess.run([f"llm_build/{str(random_uuid)}/Solution"], capture_output=True)
  File "/usr/lib/python3.10/subprocess.py", line 503, in run
    with Popen(*popenargs, **kwargs) as process:
  File "/usr/lib/python3.10/subprocess.py", line 971, in __init__
    self._execute_child(args, executable, preexec_fn, close_fds,
  File "/usr/lib/python3.10/subprocess.py", line 1863, in _execute_child
    raise child_exception_type(errno_num, err_msg, err_filename)
FileNotFoundError: [Errno 2] No such file or directory: 'llm_build/1a07c6f6-287a-11f0-8ae1-e10f5b0b7eea/Solution'

Accuracy - 0.6883468834688347
